Workbook

Sheet 修订历史
A1: 版本 | B1: 日期 | C1: 相关会议 | D1: 修订内容 | E1: 修订人
A2: V1.0.0 | B2: 40844 | D2: 创建第一稿 | E2: 李健、梁双春、胡亚希、袁静
B3: 40871 | D3: 1、增加了测量族说明 | E3: 李健、梁双春
D4: 2、明确了各性能测量上报周期
D5: 3、明确了设备入网时性能测量的准确性测试要求
D6: 4、删除多个性能测量英文名称的测量族与测量名称之间的空格。
D7: 5、删除“RRC连接建立失败次数”，因为据36.331，RRCConnectionReject未约定拒绝原因字段，无助于问题分析，同理删除“RRC连接重建失败次数”。
D8: 6、ERAB.NbrAttModQoS更名为ERAB.NbrAttMod，ERAB.NbrSuccModQoS更名为ERAB.NbrSuccMod，ERAB.NbrFailModQoS更名为ERAB.NbrFailMod。
D9: 7、ERAB.NbrReqRelEnbPerCause更名为ERAB.NbrReqRelEnb，原因在子测量名中体现。
D10: 8、ERAB.NbrReqRelEnbPerTraffic._Qci更名为ERAB.NbrReqRelEnb._Qci，业务通过QCI来区分。
D11: 9、将ERAB.NbrReqRelEnb._Qci.NormalRelease改为ERAB.NbrReqRelEnb.NormalRelease._Qci
D12: 10、删除E-RAB正常释放的原因值：（1）Detach，应对应于Detach Request消息 （2）Redirection towards 1xRTT，不适合于中国移动的网络 (3) UE Not Available for PS Service,UE不应存在E-RAB。
D13: 11、“MME释放的E-RAB数”的英文名 ERAB.NbrReqRelEnbMmeInitNoHOPerTraffic改为ERAB.NbrReqRelMmeInitNoHo
D14: 12、“成功切换释放的E-RAB数”的英文名ERAB.NbrReqRelEnbByHOPerTraffic改为ERAB.NbrReqRelEnbByHo
D15: 13、“eNB间X2切换出准备成功次数”英文名HO.SubccPrepOutInterEnbX2 改为HO.SuccPrepOutInterEnbX2
... D18: 16、增加“eNB间S1切换出完成次数”，对应于UE CONTEXT RELEASE COMMAND消息。
B19: 40877 | D19: 1、增加“eNB间切出失败的E-RAB数”，并分QCI进行统计，切换失败的E-RAB应计为掉线。 | E19: 李健
D20: 2、删除“分业务的eNB请求释放的激活E-RAB个数”，因其用途不明确。
D21: 3、将“eNB间S1切换出准备请求次数”更名为“eNB间S1切换出请求次数”，“eNB间X2切换出准备请求次数”更名为“eNB间X2切换出请求次数”
D22: 4、删除“eNB间切换出请求次数”，因为若eNB向多个X2口及S1口同都发切换请求时，不重复计数的标准不明确。
D23: 5、删除同频、异频切换出准备请求次数与成功次数，因为同、异频对准备阶段的成功率无影响。同理，切换完成阶段与同异频关系也无关。对于同异频，重点关注切换执行过程的成功率。
D24: 6、增加“同频切换出执行请求次数”、“异频切换出执行请求次数”。
D25: 7、对于切换入请求、准备、准备失败次数，不考虑eNB内，因为eNB内无准备相关信令。
D26: 8、增加了“eNB间S1切换出取消次数”和“eNB间X2切换出取消次数”
D27: 9、删除“系统间分组域切换出请求次数（EPS->CDMA2000）”。
D28: 10、来、去2G的切换，英文名字中的Gprs改为Geran。
D29: 11、增加了“2G切入成功次数”、“3G切入成功次数”。
B30: 40881 | D30: 12、(HH页）S1接口流量统计移动HL页，S1.IncNbrOctsGtpU更名为S1.IncNbrOctGtpU
D31: 13、(HH页）PDCP层的统计，原先分别使用了DRB、SRB、PDCP三个族，统一为PDCP族
D32: 14、(HH页）DRB.PdcpSduBitUL更名为PDCP.UpOctUl, DRB.PdcpSduOctDl更名为PDCP.UpOctDl，SRB.PdcpSduBitUl更名为PDCP.CpOctUl, SRB.PdcpSduBitDl更名为PDCP.CpOctDl，DRB.PdcpSduLossRateUl更名为PDCP.UpPktLossRateUl， DRB.PdcpSduDelayDl更名为PDCP.UpPktDelayDl， DRB.PdcpSduDiscardRateDl更名为PDCP.UpPktDiscardRateDl, DRB.PdcpSduAirLossRateDl更名为PDCP.UpPktLossRateDl， PDCP.NbrUl更名为PDCP.NbrPktUl，PDCP.NbrDl更名为PDCP.NbrPktDl。
D33: 15、（HI页）RRU.TrafficDrbPrbUlAssnMean更名为RRU.DtchPrbAssnMeanUl，RRU.TrafficDrbPrbDlAssnMean更名为RRU.DtchPrbAssnMeanDl，RRU.PdcchCceDlAssnMean 更名为RRU.PdcchCceUtilRadio,RRU.RachPreambleMean.Dedicated更名为RRU.RachPreambleRcvd
B34: 40882 | D34: 1、（HI页）ENBHI02“上行业务信道占用PRB平均数”->“下行业务信道占用PRB平均数” （HF页），新增MRO相关切换失败次数 | E34: 梁双春
A35: V1.1.0 | B35: 40889 | D35: 1、(HB页）ERAB.InitEstabTimeMean更名为ERAB.EstabTimeMean，ERAB.InitEstabTimeMax更名为ERAB.EstabTimeMax。 | E35: 李健、梁双春
D36: 2、(HB页）ERAB不再区分Initial E-RAB与Additional E-RAB。“初始E-RAB建立请求数”与“附加E-RAB建立请求数”合并为“E-RAB建立请求数”，“初始E-RAB建立成功数”与“附加E-RAB建立成功数”合并为“E-RAB建立成功数”。“初始E-RAB建立失败数”与“附加E-RAB建立失败数”合并为“E-RAB建立失败数”。
D37: 3、(HB页）“ERAB.NbrExistPerTraffic”的英文名为更名为 “ERAB.NbrLeft”，中文名称由“E-RAB数”改为“遗留E-RAB数”
D38: 4、（HC页）增加了性能测量“正常的eNB请求释放上下文数”(CONTEXT.AttRelEnb.Normal)
D39: 5、(HB)页ERAB.NbrReqRelEnb.NormalRelease改为ERAB.NbrReqRelEnb.Normal。
D40: 6、（HD页）“eNB间S1切换出完成次数”更名为“eNB间S1切换出成功次数”,“eNB间X2切换出完成次数”更名为“eNB间X2切换出成功次数”，英文名称不变。
D41: 7、（HB页）“小区切换入E-RAB数”更名为“切换入E-RAB数”，英文名称不变。
D42: 8、（HI)“上行PRB占用平均数”明确为PUSCH的PRB占用。
...

Sheet Index
A1: 索引 | B1: 性能参数表名 | C1: 备注 | D1: A类测量数 | E1: B类测量数 | F1: C类测量数 | G1: CA类测量数 | H1: CB类测量数 | I1: CC类测量数 | J1: 小计 | K1: A类测试数 | L1: B类测试数 | M1: 测试数
A2: HA | B2: RRC连接性能测量数据 | D2: =COUNTIF(HA!$B:$B,"A") -> 3 | E2: =COUNTIF(HA!$B:$B,"B") -> 14 | F2: =COUNTIF(HA!$B:$B,"C") -> 5 | G2: =COUNTIF(HA!$B:$B,"CA") -> 6 | H2: =COUNTIF(HA!$B:$B,"CB") -> 14 | I2: =COUNTIF(HA!$B:$B,"CC") -> 0 | J2: =SUM($D2:$H2) -> 42 | K2: =SUMPRODUCT((HA!$B$2:$B$41="A")*(HA!$M$2:$M$41="是")) -> 0 | L2: =SUMPRODUCT((HA!$B$2:$B$41="B")*(HA!$M$2:$M$41="是")) -> 0 | M2: =SUM(K2:L2) -> 0
A3: HB | B3: E-RAB性能测量数据 | D3: =COUNTIF(HB!$B:$B,"A") -> 8 | E3: =COUNTIF(HB!$B:$B,"B") -> 36 | F3: =COUNTIF(HB!$B:$B,"C") -> 10 | G3: =COUNTIF(HB!$B:$B,"CA") -> 0 | H3: =COUNTIF(HB!$B:$B,"CB") -> 12 | I3: =COUNTIF(HB!$B:$B,"CC") -> 0 | J3: =SUM($D3:$H3) -> 66 | K3: =SUMPRODUCT((HB!$B$2:$B$67="A")*(HB!$M$2:$M$67="是")) -> 6 | L3: =SUMPRODUCT((HB!$B$2:$B$67="B")*(HB!$M$2:$M$67="是")) -> 6 | M3: =SUM(K3:L3) -> 12
A4: HC | B4: 上下文统性能测量数据 | D4: =COUNTIF(HC!$B:$B,"A") -> 5 | E4: =COUNTIF(HC!$B:$B,"B") -> 10 | F4: =COUNTIF(HC!$B:$B,"C") -> 3 | G4: =COUNTIF(HC!$B:$B,"CA") -> 0 | H4: =COUNTIF(HC!$B:$B,"CB") -> 0 | I4: =COUNTIF(HC!$B:$B,"CC") -> 0 | J4: =SUM($D4:$H4) -> 18 | K4: =SUMPRODUCT((HC!$B$2:$B$19="A")*(HC!$M$2:$M$19="是")) -> 2 | L4: =SUMPRODUCT((HC!$B$2:$B$19="B")*(HC!$M$2:$M$19="是")) -> 1 | M4: =SUM(K4:L4) -> 3
A5: HD | B5: 系统内分组域切换性能测量数据 | D5: =COUNTIF(HD!$B:$B,"A") -> 18 | E5: =COUNTIF(HD!$B:$B,"B") -> 28 | F5: =COUNTIF(HD!$B:$B,"C") -> 3 | G5: =COUNTIF(HD!$B:$B,"CA") -> 2 | H5: =COUNTIF(HD!$B:$B,"CB") -> 13 | I5: =COUNTIF(HD!$B:$B,"CC") -> 0 | J5: =SUM($D5:$H5) -> 64 | K5: =SUMPRODUCT((HD!$B$2:$B$65="A")*(HD!$M$2:$M$65="是")) -> 7 | L5: =SUMPRODUCT((HD!$B$2:$B$65="B")*(HD!$M$2:$M$65="是")) -> 11 | M5: =SUM(K5:L5) -> 18
A6: HE | B6: 系统间分组域切换性能测量数据 | D6: =COUNTIF(HE!$B:$B,"A") -> 4 | E6: =COUNTIF(HE!$B:$B,"B") -> 0 | F6: =COUNTIF(HE!$B:$B,"C") -> 20 | G6: =COUNTIF(HE!$B:$B,"CA") -> 0 | H6: =COUNTIF(HE!$B:$B,"CB") -> 0 | I6: =COUNTIF(HE!$B:$B,"CC") -> 11 | J6: =SUM($D6:$H6) -> 24 | K6: =SUMPRODUCT((HE!$B$2:$B$24="A")*(HE!$M$2:$M$24="是")) -> 0 | L6: =SUMPRODUCT((HE!$B$2:$B$24="B")*(HE!$M$2:$M$24="是")) -> 0 | M6: =SUM(K6:L6) -> 0
A7: HF | B7: 基于EutranRelation的切换测量数据 | D7: =COUNTIF(HF!$B:$B,"A") -> 0 | E7: =COUNTIF(HF!$B:$B,"B") -> 11 | F7: =COUNTIF(HF!$B:$B,"C") -> 4 | G7: =COUNTIF(HF!$B:$B,"CA") -> 0 | H7: =COUNTIF(HF!$B:$B,"CB") -> 0 | I7: =COUNTIF(HF!$B:$B,"CC") -> 0 | J7: =SUM($D7:$H7) -> 15 | K7: =SUMPRODUCT((HF!$B$2:$B$16="A")*(HF!$M$2:$M$16="是")) -> 0 | L7: =SUMPRODUCT((HF!$B$2:$B$16="B")*(HF!$M$2:$M$16="是")) -> 2 | M7: =SUM(K7:L7) -> 2
A8: HG | B8: 小区寻呼性能测量数据 | D8: =COUNTIF(HG!$B:$B,"A") -> 1 | E8: =COUNTIF(HG!$B:$B,"B") -> 0 | F8: =COUNTIF(HG!$B:$B,"C") -> 0 | G8: =COUNTIF(HG!$B:$B,"CA") -> 1 | H8: =COUNTIF(HG!$B:$B,"CB") -> 0 | I8: =COUNTIF(HG!$B:$B,"CC") -> 0 | J8: =SUM($D8:$H8) -> 2 | K8: =SUMPRODUCT((HG!$B$2:$B$3="A")*(HG!$M$2:$M$3="是")) -> 0 | L8: =SUMPRODUCT((HG!$B$2:$B$3="B")*(HG!$M$2:$M$3="是")) -> 0 | M8: =SUM(K8:L8) -> 0
A9: HH | B9: 小区无线承载相关测量数据 | D9: =COUNTIF(HH!$B:$B,"A") -> 5 | E9: =COUNTIF(HH!$B:$B,"B") -> 19 | F9: =COUNTIF(HH!$B:$B,"C") -> 2 | G9: =COUNTIF(HH!$B:$B,"CA") -> 6 | H9: =COUNTIF(HH!$B:$B,"CB") -> 2 | I9: =COUNTIF(HH!$B:$B,"CC") -> 0 | J9: =SUM($D9:$H9) -> 34 | K9: =SUMPRODUCT((HH!$B$2:$B$35="A")*(HH!$M$2:$M$35="是")) -> 0 | L9: =SUMPRODUCT((HH!$B$2:$B$35="B")*(HH!$M$2:$M$35="是")) -> 0 | M9: =SUM(K9:L9) -> 0
A10: HI | B10: 无线资源利用率相关测量数据 | D10: =COUNTIF(HI!$B:$B,"A") -> 11 | E10: =COUNTIF(HI!$B:$B,"B") -> 24 | F10: =COUNTIF(HI!$B:$B,"C") -> 16 | G10: =COUNTIF(HI!$B:$B,"CA") -> 2 | H10: =COUNTIF(HI!$B:$B,"CB") -> 2 | I10: =COUNTIF(HI!$B:$B,"CC") -> 0 | J10: =SUM($D10:$H10) -> 55 | K10: =SUMPRODUCT((HI!$B$2:$B$46="A")*(HI!$M$2:$M$46="是")) -> 0 | L10: =SUMPRODUCT((HI!$B$2:$B$46="B")*(HI!$M$2:$M$46="是")) -> 0 | M10: =SUM(K10:L10) -> 0
A11: HJ | B11: SCTP偶联性能测量数据 | D11: =COUNTIF(HJ!$B:$B,"A") -> 0 | E11: =COUNTIF(HJ!$B:$B,"B") -> 3 | F11: =COUNTIF(HJ!$B:$B,"C") -> 0 | G11: =COUNTIF(HJ!$B:$B,"CA") -> 0 | H11: =COUNTIF(HJ!$B:$B,"CB") -> 4 | I11: =COUNTIF(HJ!$B:$B,"CC") -> 0 | J11: =SUM($D11:$H11) -> 7 | K11: =SUMPRODUCT((HJ!$B$2:$B$8="A")*(HJ!$M$2:$M$8="是")) -> 0 | L11: =SUMPRODUCT((HJ!$B$2:$B$8="B")*(HJ!$M$2:$M$8="是")) -> 2 | M11: =SUM(K11:L11) -> 2
A12: HK | B12: 以太网端口性能测量数据 | D12: =COUNTIF(HK!$B:$B,"A") -> 0 | E12: =COUNTIF(HK!$B:$B,"B") -> 2 | F12: =COUNTIF(HK!$B:$B,"C") -> 0 | G12: =COUNTIF(HK!$B:$B,"CA") -> 0 | H12: =COUNTIF(HK!$B:$B,"CB") -> 0 | I12: =COUNTIF(HK!$B:$B,"CC") -> 0 | J12: =SUM($D12:$H12) -> 2 | K12: =SUMPRODUCT((HK!$B$2:$B$3="A")*(HK!$M$2:$M$3="是")) -> 0 | L12: =SUMPRODUCT((HK!$B$2:$B$3="B")*(HK!$M$2:$M$3="是")) -> 0 | M12: =SUM(K12:L12) -> 0
A13: HL | B13: S1接口流量测量数据 | D13: =COUNTIF(HL!$B:$B,"A") -> 0 | E13: =COUNTIF(HL!$B:$B,"B") -> 2 | F13: =COUNTIF(HL!$B:$B,"C") -> 0 | G13: =COUNTIF(HL!$B:$B,"CA") -> 0 | H13: =COUNTIF(HL!$B:$B,"CB") -> 4 | I13: =COUNTIF(HL!$B:$B,"CC") -> 0 | J13: =SUM($D13:$H13) -> 6 | K13: =SUMPRODUCT((HL!$B$2:$B$7="A")*(HL!$M$2:$M$7="是")) -> 0 | L13: =SUMPRODUCT((HL!$B$2:$B$7="B")*(HL!$M$2:$M$7="是")) -> 0 | M13: =SUM(K13:L13) -> 0
A14: HM | B14: MAC层性能测量数据 | D14: =COUNTIF(HM!$B:$B,"A") -> 0 | E14: =COUNTIF(HM!$B:$B,"B") -> 59 | F14: =COUNTIF(HM!$B:$B,"C") -> 0 | G14: =COUNTIF(HM!$B:$B,"CA") -> 0 | H14: =COUNTIF(HM!$B:$B,"CB") -> 21 | I14: =COUNTIF(HM!$B:$B,"CC") -> 0 | J14: =SUM($D14:$H14) -> 80 | K14: =SUMPRODUCT((HM!$B$2:$B$75="A")*(HM!$M$2:$M$75="是")) -> 0 | L14: =SUMPRODUCT((HM!$B$2:$B$75="B")*(HM!$M$2:$M$75="是")) -> 0 | M14: =SUM(K14:L14) -> 0
A15: HN | B15: 小区无线信道统计数据 | D15: =COUNTIF(HN!$B:$B,"A") -> 1 | E15: =COUNTIF(HN!$B:$B,"B") -> 18 | F15: =COUNTIF(HN!$B:$B,"C") -> 0 | G15: =COUNTIF(HN!$B:$B,"CA") -> 0 | H15: =COUNTIF(HN!$B:$B,"CB") -> 0 | I15: =COUNTIF(HN!$B:$B,"CC") -> 0 | J15: =SUM($D15:$H15) -> 19 | K15: =SUMPRODUCT((HN!$B$2:$B$19="A")*(HN!$M$2:$M$19="是")) -> 0 | L15: =SUMPRODUCT((HN!$B$2:$B$19="B")*(HN!$M$2:$M$19="是")) -> 0 | M15: =SUM(K15:L15) -> 0
A16: HO | B16: ENB硬件处理负荷测量 | D16: =COUNTIF(HO!$B:$B,"A") -> 0 | E16: =COUNTIF(HO!$B:$B,"B") -> 2 | F16: =COUNTIF(HO!$B:$B,"C") -> 0 | G16: =COUNTIF(HO!$B:$B,"CA") -> 0 | H16: =COUNTIF(HO!$B:$B,"CB") -> 0 | I16: =COUNTIF(HO!$B:$B,"CC") -> 0 | J16: =SUM($D16:$H16) -> 2 | K16: =SUMPRODUCT((HO!$B$2:$B$3="A")*(HO!$M$2:$M$3="是")) -> 0 | L16: =SUMPRODUCT((HO!$B$2:$B$3="B")*(HO!$M$2:$M$3="是")) -> 0 | M16: =SUM(K16:L16) -> 0
A17: HP | B17: 小区发射功率测量 | D17: =COUNTIF(HP!$B:$B,"A") -> 0 | E17: =COUNTIF(HP!$B:$B,"B") -> 2 | F17: =COUNTIF(HP!$B:$B,"C") -> 0 | G17: =COUNTIF(HP!$B:$B,"CA") -> 0 | H17: =COUNTIF(HP!$B:$B,"CB") -> 0 | I17: =COUNTIF(HP!$B:$B,"CC") -> 0 | J17: =SUM($D17:$H17) -> 2 | K17: =SUMPRODUCT((HP!$B$2:$B$3="A")*(HP!$M$2:$M$3="是")) -> 0 | L17: =SUMPRODUCT((HP!$B$2:$B$3="B")*(HP!$M$2:$M$3="是")) -> 0 | M17: =SUM(K17:L17) -> 0
A18: HQ | B18: RRU发射功率测量 | D18: =COUNTIF(HQ!$B:$B,"A") -> 0 | E18: =COUNTIF(HQ!$B:$B,"B") -> 2 | F18: =COUNTIF(HQ!$B:$B,"C") -> 0 | G18: =COUNTIF(HQ!$B:$B,"CA") -> 0 | H18: =COUNTIF(HQ!$B:$B,"CB") -> 0 | I18: =COUNTIF(HQ!$B:$B,"CC") -> 0 | J18: =SUM($D18:$H18) -> 2 | K18: =SUMPRODUCT((HQ!$B$2:$B$3="A")*(HQ!$M$2:$M$3="是")) -> 0 | L18: =SUMPRODUCT((HQ!$B$2:$B$3="B")*(HQ!$M$2:$M$3="是")) -> 0 | M18: =SUM(K18:L18) -> 0
A19: HR | B19: 基于GSMRelation的切换测量数据 | D19: =COUNTIF(HR!$B:$B,"A") -> 0 | E19: =COUNTIF(HR!$B:$B,"B") -> 0 | F19: =COUNTIF(HR!$B:$B,"C") -> 0 | G19: =COUNTIF(HR!$B:$B,"CA") -> 0 | H19: =COUNTIF(HR!$B:$B,"CB") -> 3 | I19: =COUNTIF(HR!$B:$B,"CC") -> 0 | J19: =SUM($D19:$H19) -> 3 | K19: =SUMPRODUCT((HR!$B$2:$B$4="A")*(HR!$M$2:$M$4="是")) -> 0 | L19: =SUMPRODUCT((HR!$B$2:$B$4="B")*(HR!$M$2:$M$4="是")) -> 0 | M19: =SUM(K19:L19) -> 0
A20: HS | B20: S1接口信令测量 | D20: =COUNTIF(HS!$B:$B,"A") -> 0 | E20: =COUNTIF(HS!$B:$B,"B") -> 2 | F20: =COUNTIF(HS!$B:$B,"C") -> 0 | G20: =COUNTIF(HS!$B:$B,"CA") -> 0 | H20: =COUNTIF(HS!$B:$B,"CB") -> 0 | I20: =COUNTIF(HS!$B:$B,"CC") -> 0 | J20: =SUM($D20:$H20) -> 2 | K20: =SUMPRODUCT((HS!$B$2:$B$3="A")*(HS!$M$2:$M$3="是")) -> 0 | L20: =SUMPRODUCT((HS!$B$2:$B$3="B")*(HS!$M$2:$M$3="是")) -> 0 | M20: =SUM(K20:L20) -> 0
A21: HT | B21: 子小区测量 | D21: =COUNTIF(HT!$B:$B,"A") -> 0 | E21: =COUNTIF(HT!$B:$B,"B") -> 0 | F21: =COUNTIF(HT!$B:$B,"C") -> 0 | G21: =COUNTIF(HT!$B:$B,"CA") -> 0 | H21: =COUNTIF(HT!$B:$B,"CB") -> 4 | I21: =COUNTIF(HT!$B:$B,"CC") -> 1 | J21: =SUM($D21:$H21) -> 4 | K21: =SUMPRODUCT((HT!$B$2:$B$3="A")*(HT!$M$2:$M$3="是")) -> 0 | L21: =SUMPRODUCT((HT!$B$2:$B$3="B")*(HT!$M$2:$M$3="是")) -> 0 | M21: =SUM(K21:L21) -> 0
A22: HU | B22: 能耗相关测量 | D22: =COUNTIF(HT!$B:$B,"A") -> 0 | E22: =COUNTIF(HU!$B:$B,"B") -> 1 | F22: =COUNTIF(HU!$B:$B,"C") -> 0 | G22: =COUNTIF(HT!$B:$B,"CA") -> 0 | H22: =COUNTIF(HU!$B:$B,"CB") -> 10 | I22: =COUNTIF(HU!$B:$B,"CC") -> 0 | J22: =SUM($D22:$H22) -> 11 | K22: =SUMPRODUCT((HT!$B$2:$B$3="A")*(HT!$M$2:$M$3="是")) -> 0 | L22: =SUMPRODUCT((HT!$B$2:$B$3="B")*(HT!$M$2:$M$3="是")) -> 0 | M22: =SUM(K22:L22) -> 0
A23: HV | B23: 区分PLMN网络共享测量数据 | D23: =COUNTIF(HV!$B:$B,"A") -> 0 | E23: =COUNTIF(HV!$B:$B,"B") -> 0 | F23: =COUNTIF(HV!$B:$B,"C") -> 0 | G23: =COUNTIF(HV!$B:$B,"CA") -> 0 | H23: =COUNTIF(HV!$B:$B,"CB") -> 37 | I23: =COUNTIF(HV!$B:$B,"CC") -> 0 | J23: =SUM($D23:$H23) -> 37 | K23: =SUMPRODUCT((HT!$B$2:$B$3="A")*(HT!$M$2:$M$3="是")) -> 0 | L23: =SUMPRODUCT((HT!$B$2:$B$3="B")*(HT!$M$2:$M$3="是")) -> 0 | M23: =SUM(K23:L23) -> 0
A24: 合计 | D24: =SUM(D2:D23) -> 56 | E24: =SUM(E2:E23) -> 235 | F24: =SUM(F2:F23) -> 63 | G24: =SUM(G2:G23) -> 17 | H24: =SUM(H2:H23) -> 126 | I24: =SUM(I2:I23) -> 12 | J24: =SUM(J2:J23) -> 497 | K24: =SUM(K2:K23) -> 15 | ... M24: =SUM(M2:M23) -> 37
A27: 测量族 | B27: 测量族说明
A28: RRC | B28: RRC连接相关性能测量
A29: ERAB | B29: E-RAB相关性能测量
A30: CONTEXT | B30: UE Context相关性能测量
A31: HO | B31: 系统内切换相关性能测量
A32: IRATHO | B32: 系统间切换相关性能测量
A33: PAG | B33: 小区寻呼相关性能测量
A34: PDCP | B34: PDCP层相关性能测量
A35: RRU | B35: 无线资源利用率相关性能测量
A36: SIG | B36: 通用信令性能测量
A37: EQPT | B37: 网元物理资源性能测量
A38: S1 | B38: S1接口性能测量
... A42: EE | B42: 能耗相关统计
A44: 注1：伪测量的命名规则为： 1）._Qci对应子测量项，命名为“1"～"9"数字，并可递加扩展，如ENBHB01"每QCI平均E-RAB数"子项的名称为ERAB.NbrMeanEstab.1～ERAB.NbrMeanEstab.9； 对于备注增加了“支持扩展QCI”的测量项：允许各省在QCI10～256选定其中5个进行统计。对于该测量，不区分QCI时统计的是所有QCI统计结果的总和（即：包含QCI1~QCI9与扩展QCI的总和）。 2）._Cause对应子测量项，命名为以“Cause”开头，接仅由大小写字母、数字和“_”组成的字符串(例如为3GPP或厂家私有原因英文字符串缩写),不能包含空格； 3）._PRB对应子测量项，命名为英文字母或数字开头的字符串（仅由大小写字母、数字和“_”组成）。 4）._Stream对应子测量项，命名为英文字母或数字开头的字符串（仅由大小写字母、数字和“_”组成）。 5）._Mcs对应MCS 0-28阶，命名为“0"～"28"数字，如ENBHI40、ENBHI41 6）._PeriodSrs对应SRS周期，命名为{2, 5, 10, 20, 40, 80, 160, 320}数字，如ENBHI42、ENBHI43
A45: 注2：PM的空间粒度里写了TDD/FDD的，则均需要上报，HM14～21写了只针对TDD，则FDD无需上报

Sheet 数据上报的统一要求
A1: 序号 | B1: 数据上报的统一要求
A2: 1 | B2: 本规范中测量项日期格式均应遵照YYYY-MM-DD。
A3: 2 | B3: 本规范中字符串列表的多个数据应以英文逗号“,”分隔。
A4: 3 | B4: 本规范中列表使用的分隔符应为英文半角。
A5: 4 | B5: 本规范中要求的所有counter均需要在北向文件中上报，对于特殊情况实现方式约束如下： 1、厂家不支持上报NS。 2、厂家支持，功能未生效（包括特性未开启或功能不具备外部条件）或功能生效但无业务发生场景上报要求如下： 1）平均时延类和干扰类指标上报“-”(英文减号)。 2）其他场景上报0值。 3、现网当前和以后都无应用场景的counter上报NA。
A6: 5 | B6: 基站断链场景，不上报实例。
A7: 6 | B7: 没有开通网络共享（MOCN）的小区，不用上报区分PLMN的指标。
A8: 7 | B8: NSA,NB-IOT 不再单独维护，NSA,NB-IOT等规范内容无修订场景下，版本号和涉及到共性公共bug修改的固化到停止维护前的最后一版版本即可，不再发布更新规范。

Sheet HA
A1: 统计编码 | B1: 重要度 | C1: 英文名称 | D1: 中文名称 | E1: 定义 | F1: 触发点 | G1: 采集方式 | H1: 数据类型 | I1: 单位 | J1: 空间粒度 | K1: 时间粒度 | L1: 上报周期 | M1: 测试要求 | N1: 备注
A2: ENBHA01 | B2: B | C2: RRC.SetupTimeMean | D2: RRC连接平均建立时长 | E2: 统计RRC连接平均建立时长。 | F2: 在预先设定测量周期内，统计每一个成功建立的RRC连接的时长并将其累加，即从eNB收到“RRC CONNECTION REQUEST”消息到 eNB收到“CONNECTION SETUP COMPLETE”消息之间的间隔时长。用得到该统计周期内的总时长除以该周期内成功建立的RRC连接个数，则得到每个RRC连接的平均建立时长。 | G2: DER(n=1) | H2: 整数 | I2: ms | J2: EutranCellTdd EutranCellFdd | K2: 15分钟 | L2: 15分钟 | M2: 否 | N2: 无RRC连接建立时此值报“-”（英文减号）
A3: ENBHA02 | B3: B | C3: RRC.SetupTimeMax | D3: RRC连接最大建立时长 | E3: 统计RRC连接最大建立时长。 | F3: 在预先设定测量周期内，统计每一个成功建立的RRC连接的时长，即从eNB收到“RRC CONNECTION REQUEST”消息到 eNB收到“CONNECTION SETUP COMPLETE”消息之间的间隔时长。取该统计周期内的RRC连接时长的最大值，则得到每个RRC连接的最大建立时长。 | G3: DER(n=1) | H3: 整数 | I3: ms | J3: EutranCellTdd EutranCellFdd | K3: 15分钟 | L3: 15分钟 | M3: 否
A4: ENBHA03 | B4: B | C4: RRC.ConnMean | D4: RRC连接平均数 | E4: 统计同时存在的RRC连接平均数量。 | F4: 以1秒为间隔采样，统计小区内同时存在的RRC连接数量，然后对采样点取平均值。 | G4: SI | H4: 实数 | I4: 个 | J4: EutranCellTdd EutranCellFdd | K4: 15分钟 | L4: 15分钟 | M4: 否
A5: ENBHA03 | B5: CB | C5: RRC.ConnMean.eMTC | D5: eMTC终端RRC连接平均数 | E5: 统计同时存在的RRC连接平均数量。 | F5: 以1秒为间隔采样，统计小区内同时存在的RRC连接数量，然后对采样点取平均值。 | G5: SI | H5: 实数 | I5: 个 | J5: EutranCellTdd EutranCellFdd | K5: 15分钟 | L5: 15分钟 | M5: 否 | N5: CB条件：eMTC功能开启时，针对eMTC终端的统计
A6: ENBHA04 | B6: B | C6: RRC.ConnMax | D6: RRC连接最大数 | E6: 统计同时存在的RRC连接最大数量。 | F6: 以1秒为间隔采样，统计小区内同时存在的RRC连接数量，然后对采样点取最大值。 | G6: SI | H6: 整数 | I6: 个 | J6: EutranCellTdd EutranCellFdd | K6: 15分钟 | L6: 15分钟 | M6: 否
B7: CB | C7: RRC.ConnMax.eMTC | D7: eMTC终端RRC连接最大数 | N7: CB条件：eMTC功能开启时，针对eMTC终端的统计
A8: ENBHA04 | B8: CB | C8: RRC.ConnMax.NoneMTC | D8: 非eMTC终端RRC连接最大数 | E8: 统计同时存在的RRC连接最大数量。 | F8: 以1秒为间隔采样，统计小区内同时存在的RRC连接数量，然后对采样点取最大值。 | G8: SI | H8: 整数 | I8: 个 | J8: EutranCellTdd EutranCellFdd | K8: 15分钟 | L8: 15分钟 | M8: 否
A9: ENBHA05 | B9: A | C9: RRC.AttConnEstab | D9: RRC连接建立请求次数 | E9: 统计RRC连接建立请求的次数（含重发），并区分建立原因分别统计。 含重发是指RRC 层检测成功一次就累加一次。 | F9: eNB接收到UE发送的“RRC连接请求”（RRCConnectionRequest）消息，每个EstablishmentCause对应一个子测量项。（3GPP TS 36.331） | G9: CC | H9: 整数 | I9: 次 | J9: EutranCellTdd EutranCellFdd | K9: 15分钟 | L9: 15分钟 | M9: 否
B10: CB | C10: RRC.AttConnEstab.eMTC | D10: eMTC终端RRC连接建立请求次数 | N10: CB条件：eMTC功能开启时，针对eMTC终端的统计
B11: C | C11: RRC.AttConnEstab._Cause | D11: 分原因的RRC连接建立请求次数 | E11: 统计RRC连接建立请求的次数。 | G11: CC | H11: 整数 | I11: 次 | J11: EutranCellTdd | K11: 15分钟 | L11: 15分钟
A12: ENBHA06 | B12: A | C12: RRC.SuccConnEstab | D12: RRC连接建立成功次数 | E12: 统计RRC连接建立成功的次数，并区分建立原因分别统计。 | F12: eNB接收到UE发送的“RRC连接建立完成”（RRCConnectionSetupComplete）消息，每个EstablishmentCause对应一个子测量项。（3GPP TS 36.331） | G12: CC | H12: 整数 | I12: 次 | J12: EutranCellTdd EutranCellFdd | K12: 15分钟 | L12: 15分钟 | M12: 否
B13: CB | C13: RRC.SuccConnEstab.eMTC | D13: eMTC终端RRC连接建立成功次数 | N13: CB条件：eMTC功能开启时，针对eMTC终端的统计
B14: C | C14: RRC.SuccConnEstab._Cause | D14: 分原因的RRC连接建立成功次数 | G14: CC | H14: 整数 | I14: 次 | J14: EutranCellTdd | K14: 15分钟 | L14: 15分钟
A15: ENBHA07 | B15: B | C15: RRC.AttConnReestab | D15: RRC连接重建请求次数 | E15: 统计RRC连接重建请求次数（不计重发）,并区分重建原因分别统计。 | F15: eNB接收到UE发来的“RRC连接重建请求”（RRCConnectionReestablishmentRequest）消息，每个ReestablishmentCause对应一个子测量项。（3GPP TS 36.331） | G15: CC | H15: 整数 | I15: 次 | J15: EutranCellTdd EutranCellFdd | K15: 15分钟 | L15: 15分钟 | M15: 否
B16: CB | C16: RRC.AttConnReestab.eMTC | D16: eMTC终端RRC连接重建请求次数 | N16: CB条件：eMTC功能开启时，针对eMTC终端的统计
B17: C | C17: RRC.AttConnReestab._Cause | D17: 分原因的RRC连接重建请求次数
A18: ENBHA08 | B18: B | C18: RRC.SuccConnReestab | D18: RRC连接重建成功次数 | E18: 统计RRC连接重建成功的次数,并区分重建原因分别统计。 | F18: eNB接收到UE发来的“RRC连接重建完成”（RRCConnectionReestablishmentComplete）消息。（3GPP TS 36.331） | G18: CC | H18: 整数 | I18: 次 | J18: EutranCellTdd EutranCellFdd | K18: 15分钟 | L18: 15分钟 | M18: 否
B19: CB | C19: RRC.SuccConnReestab.eMTC | D19: eMTC终端RRC连接重建成功次数 | N19: CB条件：eMTC功能开启时，针对eMTC终端的统计
B20: B | C20: RRC.SuccConnReestab.NonSrccell | D20: RRC连接重建成功次数(非源侧小区)
B21: C | C21: RRC.SuccConnReestab._Cause | D21: 分原因的RRC连接重建成功次数
A22: ENBHA09 | B22: B | C22: RRC.ConnReleaseCsfb | D22: CSFB触发的RRC连接释放次数 | E22: 统计CSFB触发的RRC连接释放次数 | F22: eNB接收到MME发送的“初始上下文建立请求”（INITIAL CONTEXT SETUP REQUEST）消息或者“UE上下文修改请求”（UE CONTEXT MODIFICATION REQUEST）消息中携带CS Fallback Indicator，随后eNB向UE发送的RRCConnectionRelease消息中ReleaseCause=cs-FallbackHighPriority或ReleaseCause=other。(3GPP TS 36.331) | G22: CC | H22: 整数 | I22: 次 | J22: EutranCellTdd EutranCellFdd | K22: 15分钟 | L22: 15分钟 | M22: 否
B23: B | C23: RRC.ConnRelease.RedirectTo2G | D23: 重定向到2G的RRC连接释放次数 | E23: 统计LTE重定向2G的RRC连接释放次数 | F23: eNB向UE发送RRCConnectionRelease消息，RedirectedCarrierInfo=geran (3GPP TS 36.331) | G23: CC | H23: 整数 | I23: 次 | J23: EutranCellTdd EutranCellFdd | K23: 15分钟 | L23: 15分钟 | M23: 否
B24: CB | C24: RRC.ConnRelease.RedirectTo3G | D24: 重定向到3G的RRC连接释放次数 | E24: 统计LTE重定向3G的RRC连接释放次数 | F24: eNB发送RRCConnectionRelease消息，RedirectedCarrierInfo=utra-TDD或utra-FDD (3GPP TS 36.331) | G24: CC | H24: 整数 | I24: 次 | J24: EutranCellTdd EutranCellFdd | K24: 15分钟 | L24: 15分钟 | M24: 否 | N24: CB条件：存在3G场景时
B25: B | C25: RRC.ConnRelease.RedirectTo5G | D25: 重定向到5G的RRC连接释放次数 | E25: 统计LTE重定向5G的RRC连接释放次数 | F25: eNB发送RRCConnectionRelease消息，RedirectedCarrierInfo= nr-r15(3GPP TS 36.331) | G25: CC | H25: 整数 | I25: 次 | J25: EutranCellTdd EutranCellFdd | K25: 15分钟 | L25: 15分钟 | M25: 否 | N25: RedirectedCarrierInfo的取值中utra-TDD含其后续版本
A26: ENBHA10 | B26: B | C26: RRC.EffectiveConnMean | D26: 有效RRC连接平均数 | E26: 有数据传输的RRC连接平均数。以100ms为周期，记录有效RRC连接数，并取各个周期的平均值。在每100ms之内，若某RRC相关的任意一个E-RAB有用户面数据传输或缓存不为空，则视该RRC连接是有效的。在每100ms内，逐毫秒累加计数，但不重复累加同一有效RRC连接数。 | F26: 无 | G26: SI | H26: 实数 | I26: 次 | J26: EutranCellTdd EutranCellFdd | K26: 15分钟 | L26: 15分钟 | M26: 否
A27: ENBHA11 | B27: B | C27: RRC.EffectiveConnMax | D27: 有效RRC连接最大数 | E27: 有数据传输的RRC连接最大数。以100ms为周期，记录有效RRC连接数，并取各个周期的最大值。在每100ms之内，若某RRC相关的任意一个E-RAB有用户面数据传输或缓存不为空，则视该RRC连接是有效的。在每100ms内，逐毫秒累加计数，但不重复累加同一有效RRC连接数。 | F27: 无 | G27: SI | H27: 整数 | I27: 次 | J27: EutranCellTdd EutranCellFdd | K27: 15分钟 | L27: 15分钟 | M27: 否
A28: ENBHA12 | B28: CA | C28: RRC.ActiveMeanNbrPCellDl | D28: 以本小区为PCell的下行CA平均激活UE数 | E28: 在小区范围内，定期采样所有UE（已连接），统计得到此时将本小区做为Pcell的下行CA激活UE数，采样周期不超过1秒，在统计周期末求平均。 单独统计2CC和3CC的CA平均激活UE数。 | F28: 无 | G28: SI | H28: 实数 | I28: 个 | J28: EutranCellTdd EutranCellFdd | K28: 15分钟 | L28: 15分钟 | M28: 否 | N28: CA条件：开启载波聚合功能时，进行相关统计
B29: CA | C29: RRC.ActiveMeanNbrPCellDl.2CC | D29: 以本小区为PCell的下行2CC的CA平均激活UE数 | F29: 无 | G29: SI | H29: 实数 | I29: 个 | J29: EutranCellTdd EutranCellFdd | K29: 15分钟 | L29: 15分钟 | M29: 否
B30: CB | C30: RRC.ActiveMeanNbrPCellDl.3CC | D30: 以本小区为PCell的下行3CC的CA平均激活UE数 | F30: 无 | G30: SI | H30: 实数 | I30: 个 | J30: EutranCellTdd EutranCellFdd | K30: 15分钟 | L30: 15分钟 | M30: 否 | N30: CB条件：开启载波聚合功能且打开3CC功能时进行统计
A31: ENBHA13 | B31: CB | C31: RRC.MeanNbrCoMPUl | D31: 进入上行CoMP状态平均UE数 | E31: 定期采样所有UE，统计小区内进入上行CoMP状态（指符合CoMP门限阈值要求）的UE数，采样周期不超过1秒，在统计周期末求平均。 | F31: 无 | G31: SI | H31: 实数 | I31: 个 | J31: EutranCellTdd EutranCellFdd | K31: 15分钟 | L31: 15分钟 | M31: 否 | N31: CB条件：开启CoMP功能时，进行相关统计
A32: ENBHA14 | B32: B | C32: RRC.AdmissionConnMean | D32: 接纳用户平均数 | E32: 统计接纳的同时存在的连接用户平均数量。 | F32: 此测量参数通过预先设定测量时间间隔采样，得到给定小区同时存在接纳连接用户数量，包括本小区RRC连接用户数和CA场景下本小区作为SCell接入（配置或激活）的用户数，对所有采样点取平均值。 | G32: SI | H32: 实数 | I32: 个 | J32: EutranCellTdd EutranCellFdd | K32: 15分钟 | L32: 15分钟 | M32: 否
A33: ENBHA15 | B33: B | C33: RRC.AdmissionConnMax | D33: 接纳用户最大数 | E33: 统计接纳的同时存在的连接用户最大数量。 | F33: 此测量参数通过预先设定测量时间间隔采样，得到给定小区同时存在接纳连接用户数量，包括本小区RRC连接用户数和CA场景下本小区作为SCell接入（配置或激活）的用户数，对所有采样点取最大值。 | G33: SI | H33: 整数 | I33: 个 | J33: EutranCellTdd EutranCellFdd | K33: 15分钟 | L33: 15分钟 | M33: 否
A34: ENBHA16 | B34: CB | C34: RRC.MeanNbrCoMPDl | D34: 进入下行CoMP状态平均UE数 | E34: 定期采样所有UE，统计小区内进入下行CoMP状态（指符合CoMP门限阈值要求）的UE数，采样周期不超过1秒，在统计周期末求平均。 | F34: 无 | G34: SI | H34: 实数 | I34: 个 | J34: EutranCellTdd EutranCellFdd | K34: 15分钟 | L34: 15分钟 | M34: 否 | N34: CB条件：开启CoMP功能时，进行相关统计
A35: ENBHA17 | B35: A | C35: RRC.FailConnEstab | D35: RRC连接建立不含重发失败次数 | E35: 统计RRC连接建立失败的次数，并区分建立失败原因分别统计。 | F35: eNB向UE发送RRCConnectionRequest消息之后未收到“RRC连接建立完成”（RRCConnectionSetupComplete）消息，或eNB向UE发送RRCConnectionReject消息。针对单UE同一次接入，多个失败计算为1。每个失败原因对应一个子测量项。（3GPP TS 36.331） | G35: CC | H35: 整数 | I35: 次 | J35: EutranCellTdd EutranCellFdd | K35: 15分钟 | L35: 15分钟 | M35: 否
B36: C | C36: RRC.FailConnEstab._Cause | D36: 分原因的RRC连接建立失败次数 | G36: CC | H36: 整数 | I36: 次 | J36: EutranCellTdd EutranCellFdd | K36: 15分钟 | L36: 15分钟 | M36: 否
A37: ENBHA18 | B37: CA | C37: RRC.ActiveMeanNbrPCellUl | D37: 以本小区为PCell的上行CA平均激活UE数 | E37: 在小区范围内，定期采样所有UE（已连接），统计得到此时将本小区做为Pcell的上行CA激活UE数，采样周期不超过1秒，在统计周期末求平均。 | F37: 无 | G37: SI | H37: 实数 | I37: 个 | J37: EutranCellTdd EutranCellFdd | K37: 15分钟 | L37: 15分钟 | M37: 否 | N37: CA条件：开启载波聚合功能时，进行相关统计
A38: ENBHA19 | B38: CA | C38: RRC.ConfigMeanNbrPCellDl | D38: 以本小区为PCell的下行CA平均配置UE数 | E38: 在小区范围内，定期采样所有UE（已连接），统计得到此时将本小区做为Pcell的下行CA配置UE数，采样周期不超过1秒，在统计周期末求平均。 单独统计2CC和3CC的CA平均配置UE数。 | F38: 无 | G38: SI | H38: 实数 | I38: 个 | J38: EutranCellTdd EutranCellFdd | K38: 15分钟 | L38: 15分钟 | M38: 否 | N38: CA条件：开启载波聚合功能时，进行相关统计
B39: CA | C39: RRC.ConfigMeanNbrPCellDl.2CC | D39: 以本小区为PCell的下行2CC的CA平均配置UE数 | E39: 在小区范围内，定期采样所有UE（已连接），统计得到此时将本小区做为Pcell的下行CA激活UE数，采样周期不超过1秒，在统计周期末求平均。 | F39: 无 | G39: SI | H39: 实数 | I39: 个 | J39: EutranCellTdd EutranCellFdd | K39: 15分钟 | L39: 15分钟 | M39: 否
B40: CB | C40: RRC.ConfigMeanNbrPCellDl.3CC | D40: 以本小区为PCell的下行3CC的CA平均配置UE数 | E40: 在小区范围内，定期采样所有UE（已连接），统计得到此时将本小区做为Pcell的下行CA激活UE数，采样周期不超过1秒，在统计周期末求平均。 | F40: 无 | G40: SI | H40: 实数 | I40: 个 | J40: EutranCellTdd EutranCellFdd | K40: 15分钟 | L40: 15分钟 | M40: 否 | N40: CB条件：开启载波聚合功能且打开3CC功能时进行统计
...

Sheet HB
A1: 统计编码 | B1: 重要度 | C1: 英文名称 | D1: 中文名称 | E1: 定义 | F1: 触发点 | G1: 采集方式 | H1: 数据类型 | I1: 单位 | J1: 空间粒度 | K1: 时间粒度 | L1: 上报周期 | M1: 测试要求 | N1: 备注
A2: ENBHB01 | B2: B | C2: ERAB.NbrMeanEstab | D2: 平均E-RAB数 | E2: 统计小区内同时存在的E-RAB平均个数。 | F2: 此测量参数通过预先设定测量时间间隔采样（目前固定为1秒间隔），得到给定小区同时存在的E-RAB数量，然后取平均值。 | G2: SI | H2: 实数 | I2: 个 | J2: EutranCellTdd EutranCellFdd | K2: 15分钟 | L2: 15分钟 | M2: 否
B3: CB | C3: ERAB.NbrMeanEstab.eMTC | D3: eMTC终端平均E-RAB数 | N3: CB条件：eMTC功能开启时，针对eMTC终端的统计
B4: B | C4: ERAB.NbrMeanEstab._Qci | D4: 每QCI平均E-RAB数 | N4: 支持扩展QCI
A5: ENBHB02 | B5: B | C5: ERAB.EstabTimeMean | D5: E-RAB平均建立时长 | E5: 统计E-RAB平均建立时长。 | F5: （1）统计从eNB收到MME发送的INITIAL CONTEXT SETUP REQUEST到eNB向MME发送INITIAL CONTEXT SETUP RESPONSE之间的时间间隔，不考虑消息中含有的E-RAB数。 （2）统计从eNB收到MME发送E-RAB Setup Request消息至eNB向MME发送E-RAB Setup Response之间的间隔时长，不考虑消息中含有的E-RAB数。 本测量项为上述两类时间间隔累加后，除以这两类消息数得到的算术平均值。注：只统计成功建立的E-RAB。 | G5: DER(n=1) | H5: 整数 | I5: 毫秒 | J5: EutranCellTdd EutranCellFdd | K5: 15分钟 | L5: 15分钟 | M5: 否 | N5: 无ERAB建立时此值报“-”（英文减号）
A6: ENBHB03 | B6: B | C6: ERAB.EstabTimeMax | D6: E-RAB最大建立时长 | E6: 统计E-RAB最大建立时长。 | F6: （1）统计从eNB收到MME发送的INITIAL CONTEXT SETUP REQUEST到eNB向MME发送INITIAL CONTEXT SETUP RESPONSE之间的时间间隔，不考虑消息中含有的E-RAB数。 （2）统计从eNB收到MME发送E-RAB Setup Request消息至eNB向MME发送E-RAB Setup Response之间的间隔时长，不考虑消息中含有的E-RAB数。 本测量项为上述两类时间隔的最大值。注：只统计成功建立的E-RAB。 | G6: DER(n=1) | H6: 整数 | I6: 毫秒 | J6: EutranCellTdd EutranCellFdd | K6: 15分钟 | L6: 15分钟 | M6: 否
A7: ENBHB04 | B7: B | C7: ERAB.NbrHoInc | D7: 切换入E-RAB数 | E7: 统计小区切换入E-RAB个数。 | F7: eNB收到UE发送的“RRC连接重配置完成”消息 （RRCConnectionReconfigurationComplete），指示UE小区切换入时，统计该RRC连接对应的E-RAB个数，包括系统间的切换。（3GPP TS 23.401，TS 36.331和TS 36.413） | G7: CC | H7: 整数 | I7: 个 | J7: EutranCellTdd EutranCellFdd | K7: 15分钟 | L7: 15分钟 | M7: 否
B8: CB | C8: ERAB.NbrHoInc.eMTC | D8: eMTC终端切换入E-RAB数 | N8: CB条件：eMTC功能开启时，针对eMTC终端的统计
B9: B | C9: ERAB.NbrHoInc._Qci | D9: 每QCI切换入E-RAB数 | N9: 支持扩展QCI
A10: ENBHB05 | B10: A | C10: ERAB.NbrAttEstab | D10: E-RAB建立请求数 | E10: 统计请求建立的E-RAB个数，并该按业务类型分类统计。 | F10: eNB接收到MME发来的“初始上下文建立请求消息”（INITIAL CONTEXT SETUP REQUEST）或 “E-RAB建立请求”（E-RAB SETUP REQUEST）消息，消息中包含的E-RAB个数。每个业务类型对应一个子测量项。（3GPP TS 36.413）。 | G10: CC | H10: 整数 | I10: 个 | J10: EutranCellTdd EutranCellFdd | K10: 15分钟 | L10: 15分钟 | M10: 是
B11: CB | C11: ERAB.NbrAttEstab.eMTC | D11: eMTC终端E-RAB建立请求数 | N11: CB条件：eMTC功能开启时，针对eMTC终端的统计
B12: B | C12: ERAB.NbrAttEstab._Qci | D12: 分QCI的E-RAB建立请求数 | N12: 支持扩展QCI
A13: ENBHB06 | B13: A | C13: ERAB.NbrSuccEstab | D13: E-RAB建立成功数 | E13: 统计E-RAB建立成功个数，并该按业务类型分类统计。 | F13: eNB向MME发送“初始上下文建立响应”（INITIAL CONTEXT SETUP RESPONSE）消息或“E-RAB建立响应”（E-RAB SETUP RESPONSE）消息中，成功建立的E-RAB个数；并包括不直接造成通话失败的流程冲突导致E-RAB建立中断次数。每个业务类型对应一个子测量项。（3GPP TS 36.413） 单独统计流程冲突导致E-RAB建立中断次数，场景为VoLTE业务弱场起呼触发FlashCsfb（bSRVCC规避）导致的E-RAB建立流程中断，或ERAB建立完成前发起切换流程。因为此类流程冲突不会直接造成通话失败，故包含在E-RAB建立成功数中。 | G13: CC | H13: 整数 | I13: 个 | J13: EutranCellTdd EutranCellFdd | K13: 15分钟 | L13: 15分钟 | M13: 是
B14: CB | C14: ERAB.NbrSuccEstab.eMTC | D14: eMTC终端E-RAB建立成功数 | N14: CB条件：eMTC功能开启时，针对eMTC终端的统计
B15: B | C15: ERAB.NbrSuccEstab._Qci | D15: 分QCI的E-RAB建立成功数 | N15: 支持扩展QCI
B16: C | C16: ERAB.NbrSuccEstab._Qci.Conflict | D16: 流程冲突导致E-RAB建立中断次数
A17: ENBHB07 | B17: B | C17: ERAB.NbrFailEstab | D17: E-RAB建立失败数 | E17: 统计E-RAB建立失败个数，并该按失败原因分类统计。 | F17: eNB向MME发送“初始上下文建立响应”（INITIAL CONTEXT SETUP RESPONSE）消息和“初始上下文建立失败”（INITIAL CONTEXT SETUP FAILURE）中建立失败的E-RAB个数，或eNB向MME发送“E-RAB 建立响应”（E-RAB SETUP RESPONSE）消息中建立失败的-RAB个数，每个原因对应一个子测量项。 无线资源不足指准入控制中由于用户数、ERAB数目、PRB资源、SRS数目、PUCCH资源等受限造成的E-RAB建立不成功。 无线接口进程失败指空口信令交互相关定时器超时等造成的E-RAB建立不成功，包括UE无响应等现象。 | G17: CC | H17: 整数 | I17: 个 | J17: EutranCellTdd EutranCellFdd | K17: 15分钟 | L17: 15分钟 | M17: 否 | N17: 1)S1AP消息相关的性能测量中的伪测量._Cause，在实现时建议使用CauseRadioNetwork[N]、CauseTransport[N]、CauseNas[N]、CauseProtocol[N]、CauseMisc[N]的形式，其中，N是一个大于等于0的整数，如CauseRadioNetwork[0]、CauseRadioNetwork[1]、CauseRadioNetwork[2]……，CauseRadioNetwork[N]代表的含义，可参见36.413 的9.3节。 2)CB条件：eMTC功能开启时，针对eMTC终端的统计
B18: CB | C18: ERAB.NbrFailEstab.eMTC | D18: eMTC终端E-RAB建立失败数
B19: B | C19: ERAB.NbrFailEstab.CauseTransport | D19: 传输层原因的E-RAB建立失败数
B20: B | C20: ERAB.NbrFailEstab.CauseRadioResourcesNotAvailable | D20: 无线资源不足原因导致的E-RAB建立失败数
B21: C | C21: ERAB.NbrFailEstab.CauseFailureInRadioInterfaceProcedure | D21: 无线接口进程失败原因导致的E-RAB建立失败数
B22: C | C22: ERAB.NbrFailEstab._Cause | D22: 分原因的E-RAB建立失败数
B23: C | C23: ERAB.NbrFailEstab._Qci._Cause | D23: 分QCI分原因的E-RAB建立失败数
A24: ENBHB08 | B24: B | C24: ERAB.NbrAttMod | D24: E-RAB修改请求数 | E24: 统计E-RAB修改请求的E-RAB个数，应该按业务类型分类统计。 | F24: eNB接收到MME发送的“E-RAB修改请求”（E-RAB MODIFY REQUEST）消息。每个业务类型对应一个子测量项。（3GPP TS 36.413） | G24: CC | H24: 整数 | I24: 个 | J24: EutranCellTdd EutranCellFdd | K24: 15分钟 | L24: 15分钟 | M24: 是
B25: B | C25: ERAB.NbrAttMod._Qci | D25: 分QCI的E-RAB修改请求数
A26: ENBHB09 | B26: B | C26: ERAB.NbrSuccMod | D26: E-RAB修改成功数 | E26: 统计E-RAB修改成功个数，应该按业务类型分类统计。 | F26: eNB向MME发送“E-RAB修改响应”（E-RAB MODIFY RESPONSE）消息。以目标业务类型(QCI)为统计对象，每个业务类型对应一个子测量项。（3GPP TS 36.413） | G26: CC | H26: 整数 | I26: 个 | J26: EutranCellTdd EutranCellFdd | K26: 15分钟 | L26: 15分钟 | M26: 是
B27: B | C27: ERAB.NbrSuccMod._Qci | D27: 分QCI的E-RAB修改成功数
A28: ENBHB10 | B28: B | C28: ERAB.NbrFailMod | D28: E-RAB修改失败数 | E28: 统计E-RAB修改失败个数，应该按失败原因分类统计。 | F28: eNB向MME发送“E-RAB修改响应”（E-RAB MODIFY RESPONSE）消息，指示E-RAB修改失败的个数，每个原因对应一个子测量项。（3GPP TS 36.413） | G28: CC | H28: 整数 | I28: 个 | J28: EutranCellTdd EutranCellFdd | K28: 15分钟 | L28: 15分钟 | M28: 是
B29: C | C29: ERAB.NbrFailMod._Cause | D29: 分原因的E-RAB修改失败数
A30: ENBHB11 | B30: A | C30: ERAB.NbrReqRelEnb | D30: eNB请求释放的E-RAB数 | E30: 统计eNB请求释放的E-RAB个数 | F30: eNB向MME发送“E-RAB释放指示”（E-RAB RELEASE INDICATION）或“UE上下文释放请求(UE CONTEXT RELEASE REQUEST)”消息或S1AP Reset消息，消息中含有要求释放的E-RAB个数，每个原因对应一个子测量项。其中，E-RAB正常释放的原因包括：User Inactivity, CS Fallback triggered, Inter-RAT Redirection、UE Not Available for PS Service、Redirection towards 1xRTT。（3GPP TS 36.413） | G30: CC | H30: 整数 | I30: 个 | J30: EutranCellTdd EutranCellFdd | K30: 15分钟 | L30: 15分钟 | M30: 是
B31: CB | C31: ERAB.NbrReqRelEnb.eMTC | D31: eMTC终端eNB请求释放的E-RAB数 | E31: 统计eMTC终端eNB请求释放的E-RAB数 | N31: CB条件：eMTC功能开启时，针对eMTC终端的统计
B32: A | C32: ERAB.NbrReqRelEnb.CauseUserInactivity | D32: 用户不活动原因eNB请求释放的E-RAB数 | E32: 统计用户不活动原因eNB请求释放的E-RAB个数
B33: C | C33: ERAB.NbrReqRelEnb._Cause | D33: 分原因的eNB请求释放的E-RAB数 | E33: 按释放原因分类统计eNB请求释放的E-RAB个数 | H33: 整数 | K33: 15分钟 | L33: 15分钟
B34: B | C34: ERAB.NbrReqRelEnb._Qci | D34: 分QCI的eNB请求释放的E-RAB数 | E34: 按QCI分类统计eNB请求释放的E-RAB个数 | N34: 支持扩展QCI
B35: B | C35: ERAB.NbrReqRelEnb._Qci._Cause | D35: 分QCI分原因的eNB请求释放的E-RAB数 | E35: 按QCI按释放原因分类统计eNB请求释放的E-RAB个数
B36: A | C36: ERAB.NbrReqRelEnb.Normal | D36: 正常的eNB请求释放的E-RAB数 | E36: 统计eNB请求正常释放的E-RAB个数
B37: CB | C37: ERAB.NbrReqRelEnb.Normal.eMTC | D37: eMTC终端正常的eNB请求释放的E-RAB数 | E37: 统计eNB请求正常释放的E-RAB个数 | H37: 整数 | K37: 15分钟 | L37: 15分钟 | N37: CB条件：eMTC功能开启时，针对eMTC终端的统计
B38: B | C38: ERAB.NbrReqRelEnb.Normal._Qci | D38: 分QCI的正常的eNB请求释放的E-RAB数 | E38: 分业务类型（QCI）分类统计eNB请求正常释放的E-RAB数 | N38: 支持扩展QCI
A39: ENBHB12 | B39: A | C39: ERAB.HoFail | D39: 切出失败的E-RAB数 | E39: 统计切出过程中，未能切换的E-RAB数，并按QCI分类进行统计。由于eNB内的切换属内部流程，无法约定触发点，因此不统计在内。 | F39: （1）对于基于S1接口的成功切换，统计MME发给eNB的Handover Command消息中包括的E-RABs to Release List IE 中的E-RAB个数。（3GPP TS 36.413） （2）对于基于X2接口的成功切换，target eNB发给Source eNB的Handover Request ACK消息中的E-RABs Not Admitted List IE 中的E-RAB数（3GPP TS 36.423） 注：在网络开启Multiple HO功能时，只统计被选中的目标小区对应的Handover Command和Handover Request ACK消息。 | G39: CC | H39: 整数 | I39: 个 | J39: EutranCellTdd EutranCellFdd | K39: 15分钟 | L39: 15分钟 | M39: 是
B40: CB | C40: ERAB.HoFail.eMTC | D40: eMTC终端正切出失败的E-RAB数 | N40: CB条件：eMTC功能开启时，针对eMTC终端的统计
...

Sheet HC
A1: 统计编码 | B1: 重要度 | C1: 英文名称 | D1: 中文名称 | E1: 定义 | F1: 触发点 | G1: 采集方式 | H1: 数据类型 | I1: 单位 | J1: 空间粒度 | K1: 时间粒度 | L1: 上报周期 | M1: 测试要求 | N1: 备注
A2: ENBHC01 | B2: B | C2: CONTEXT.AttInitalSetup | D2: 初始上下文建立请求次数 | E2: 统计初始上下文建立请求次数。 | F2: eNB接收到MME发送的“初始上下文建立请求”（INITIAL CONTEXT SETUP REQUEST）消息。（3GPP TS 36.413） | G2: CC | H2: 整数 | I2: 个 | J2: EutranCellTdd EutranCellFdd | K2: 15分钟 | L2: 15分钟 | M2: 是 | N2: CS Fallback Indicator 的定义为:ENUMERATED(CS Fallback required, … , CS Fallback High Priority)。统计CSFB触发的次数，可以用“initial Context Setup Request（HC01） + Ue context Modification Request（HC04）”，上述两条消息都携带IE为“Cs Fallback”。
B3: B | C3: CONTEXT.AttInitalSetup.Csfb | D3: CSFB初始上下文建立请求次数 | E3: 统计CSFB触发的上下文建立次数 | F3: eNB接收到MME发送的“初始上下文建立请求”（INITIAL CONTEXT SETUP REQUEST）消息,并携带CS Fallback Indicator 请求CS业务. 。（3GPP TS 36.413） | G3: CC | H3: 整数 | I3: 个 | J3: EutranCellTdd EutranCellFdd | K3: 15分钟 | L3: 15分钟 | M3: 否
A4: ENBHC02 | B4: A | C4: CONTEXT.SuccInitalSetup | D4: 初始上下文建立成功次数 | E4: 统计初始上下文建立成功次数。 | F4: eNB向MME发送“初始上下文建立响应”（INITIAL CONTEXT SETUP RESPONSE）消息。（3GPP TS 36.413） | G4: CC | H4: 整数 | I4: 个 | J4: EutranCellTdd EutranCellFdd | K4: 15分钟 | L4: 15分钟 | M4: 是
B5: B | C5: CONTEXT.SuccInitalSetup.Csfb | D5: CSFB初始上下文建立成功次数 | E5: 统计CSFB触发的初始上下文建立成功次数
A6: ENBHC03 | B6: B | C6: CONTEXT.FailInitalSetup | D6: 初始上下文建立失败次数 | E6: 统计初始上下文建立失败次数，应该按失败原因分类统计。 | F6: eNB向MME发送“初始上下文建立失败”（INITIAL CONTEXT SETUP FAILURE）消息，或定时器超时，指示初始上下文建立失败，每个原因对应一个子测量项。（3GPP TS 36.413） | G6: CC | H6: 整数 | I6: 个 | J6: EutranCellTdd EutranCellFdd | K6: 15分钟 | L6: 15分钟 | M6: 否
B7: C | C7: CONTEXT.FailInitalSetup._Cause | D7: 分原因的初始上下文建立失败次数
A8: ENBHC04 | B8: B | C8: CONTEXT.AttMod | D8: 上下文修改请求次数 | E8: 统计MME发起的请求修改上下文次数。 | F8: eNB收到MME发送的“UE 上下文修改请求”（UE CONTEXT MODIFICATION REQUEST）消息（3GPP TS 36.413）。 | G8: CC | H8: 整数 | I8: 个 | J8: EutranCellTdd EutranCellFdd | K8: 15分钟 | L8: 15分钟 | M8: 否 | N8: CS Fallback Indicator 的定义为:ENUMERATED(CS Fallback required, … , CS Fallback High Priority)。统计CSFB触发的次数，可以用“initial Context Setup Request（HC01） + Ue context Modification Request（HC04）”，上述两条消息都携带IE为“Cs Fallback”。
B9: B | C9: CONTEXT.AttMod.Csfb | D9: CSFB上下文修改请求次数 | E9: 统计CSFB触发的上下文修改次数 | F9: eNB收到MME发送的“UE 上下文修改请求”（UE CONTEXT MODIFICATION REQUEST）消息,并携带CS Fallback Indicator 请求CS业务.（3GPP TS 36.413）。 | G9: CC | H9: 整数 | I9: 个 | K9: 15分钟 | L9: 15分钟
A10: ENBHC05 | B10: B | C10: CONTEXT.SuccMod | D10: 上下文修改成功次数 | E10: 统计MME发起的上下文修改成功次数。 | F10: eNB向MME发送“UE 上下文修改响应”（UE CONTEXT MODIFICATION RESPONSE）消息。（3GPP TS 36.413） | G10: CC | H10: 整数 | I10: 个 | J10: EutranCellTdd EutranCellFdd | K10: 15分钟 | L10: 15分钟 | M10: 否
B11: B | C11: CONTEXT.SuccMod.Csfb | D11: CSFB上下文修改成功次数 | E11: 统计CSFB触发的的上下文修改成功次数
A12: ENBHC06 | B12: B | C12: CONTEXT.FailMod | D12: 上下文修改失败次数 | E12: 统计MME发起的上下文修改失败次数。 | F12: eNB向MME发送“UE 上下文修改失败”（UE CONTEXT MODIFICATION FAILURE）消息，或定时器超时，指示上下文修改失败。（3GPP TS 36.413） | G12: CC | H12: 整数 | I12: 个 | J12: EutranCellTdd EutranCellFdd | K12: 15分钟 | L12: 15分钟 | M12: 否
A13: ENBHC07 | B13: A | C13: CONTEXT.AttRelEnb | D13: eNB请求释放上下文数 | E13: 统计eNB发起的请求释放上下文个数，并应该按释放原因分类统计。 | F13: eNB向MME发送“UE 上下文释放请求”（UE CONTEXT RELEASE REQUEST）消息或者S1 Reset消息中包含的上下文个数，每个原因对应一个子测量项，其中正常释放的原因包括：User Inactivity, CS Fallback triggered, Inter-RAT Redirection、UE Not Available for PS Service、Redirection towards 1xRTT。（3GPP TS 36.413） 注：eNB等待INITIAL CONTEXT SETUP REQUEST消息超时，随后eNB发起的UE CONTEXT RELEASE REQUEST消息不统计。 | G13: CC | H13: 整数 | I13: 个 | J13: EutranCellTdd EutranCellFdd | K13: 15分钟 | L13: 15分钟 | M13: 否
B14: A | C14: CONTEXT.AttRelEnb.CauseUserInactivity | D14: 用户不活动原因eNB请求释放上下文数
B15: C | C15: CONTEXT.AttRelEnb._Cause | D15: 分原因的eNB请求释放上下文数
B16: A | C16: CONTEXT.AttRelEnb.Normal | D16: 正常的eNB请求释放上下文数
A17: ENBHC08 | B17: B | C17: CONTEXT.AttRelMme | D17: MME请求释放上下文数 | E17: 统计MME发起的要求释放上下文个数，并应该按释放原因分类统计。 | F17: eNB收到MME发送的“UE 上下文释放命令”（UE CONTEXT RELEASE COMMAND）消息或者S1 Reset消息中包含的上下文个数，每个原因对应一个子测量项。（3GPP TS 36.413） | G17: CC | H17: 整数 | I17: 个 | J17: EutranCellTdd EutranCellFdd | K17: 15分钟 | L17: 15分钟 | M17: 否
B18: C | C18: CONTEXT.AttRelMme._Cause | D18: 分原因的MME请求释放上下数
A19: ENBHC09 | B19: A | C19: CONTEXT.NbrLeft | D19: 遗留上下文个数 | E19: 统计本采集周期结束时已经存在UE CONTEXT个数。 | F19: 当采集周期结束时，测量当前小区已经存在的UE CONTEXT个数。（3GPP TS 36.413） | G19: Gauge | H19: 整数 | I19: 个 | J19: EutranCellTdd EutranCellFdd | K19: 15分钟 | L19: 15分钟 | M19: 是

Sheet HD
A1: 统计编码 | B1: 重要度 | C1: 英文名称 | D1: 中文名称 | E1: 定义 | F1: 触发点 | G1: 采集方式 | H1: 数据类型 | I1: 单位 | J1: 空间粒度 | K1: 时间粒度 | L1: 上报周期 | M1: 测试要求 | N1: 备注
A2: ENBHD01 | B2: A | C2: HO.AttOutInterEnbS1 | D2: eNB间S1切换出请求次数 | E2: 统计eNB间S1接口的切换出请求次数。单独统计QCI=1和2的 次数。 | F2: 源eNB向MME发送的“切换请求”消息（HANDOVER REQUIRED）（3GPP TS 36.413），指示eNB间通过S1接口的切换出准备请求。向不同小区发送的同一切换准备请求，需要重复统计。 | G2: CC | H2: 整数 | I2: 次 | J2: EutranCellTdd EutranCellFdd | K2: 15分钟 | L2: 15分钟 | M2: 是
B3: CB | C3: HO.AttOutInterEnbS1.eMTC | D3: eMTC终端eNB间S1切换出请求次数 | N3: CB条件：eMTC功能开启时，针对eMTC终端的统计
B4: A | C4: HO.AttOutInterEnbS1.1 | D4: VoLTE用户eNB间S1切换出请求次数
B5: A | C5: HO.AttOutInterEnbS1.2 | D5: QCI2承载eNB间S1切换出请求次数
A6: ENBHD02 | B6: B | C6: HO.SuccOutPrepInterEnbS1 | D6: eNB间S1切换出准备成功次数 | E6: 统计eNB间通过S1接口的切换出准备成功次数。 单独统计QCI=1的次数。 | F6: 源eNB收到MME发送的“切换命令”消息（HANDOVER COMMAND）（3GPP TS 36.413），指示eNB间S1接口切换出准备成功。 | G6: CC | H6: 整数 | I6: 次 | J6: EutranCellTdd EutranCellFdd | K6: 15分钟 | L6: 15分钟 | M6: 是
B7: CB | C7: HO.SuccOutPrepInterEnbS1.eMTC | D7: eMTC终端eNB间S1切换出准备成功次数 | N7: CB条件：eMTC功能开启时，针对eMTC终端的统计
B8: B | C8: HO.SuccOutPrepInterEnbS1.1 | D8: VoLTE用户eNB间S1切换出准备成功次数 | E8: 统计eNB间通过S1接口的切换出准备成功次数。 | F8: 源eNB收到MME发送的“切换命令”消息（HANDOVER COMMAND）（3GPP TS 36.413），指示eNB间S1接口切换出准备成功。 | G8: CC | H8: 整数 | I8: 次 | K8: 15分钟 | L8: 15分钟 | M8: 是
A9: ENBHD03 | B9: B | C9: HO.AttOutExecInterEnbS1 | D9: eNB间S1切换出执行请求次数 | E9: 统计eNB间通过S1接口的切换出执行请求次数。 单独统计QCI=1的次数。 | F9: eNB向UE发送携带mobilityControlInfo 的“RRC连接重配置”消息（RRC Connection Reconfiguration），表示eNB间S1切换出执行请求。（3GPP TS 36.331） | G9: CC | H9: 整数 | I9: 次 | J9: EutranCellTdd EutranCellFdd | K9: 15分钟 | L9: 15分钟 | M9: 否
B10: CB | C10: HO.AttOutExecInterEnbS1.eMTC | D10: eMTC终端eNB间S1切换出执行请求次数 | N10: CB条件：eMTC功能开启时，针对eMTC终端的统计
B11: B | C11: HO.AttOutExecInterEnbS1.1 | D11: VoLTE用户eNB间S1切换出执行请求次数 | E11: 统计eNB间通过S1接口的切换出执行请求次数。 | F11: eNB向UE发送携带mobilityControlInfo 的“RRC连接重配置”消息（RRC Connection Reconfiguration），表示eNB间S1切换出执行请求。（3GPP TS 36.331） | G11: CC | H11: 整数 | I11: 次 | K11: 15分钟 | L11: 15分钟 | M11: 否
A12: ENBHD04 | B12: A | C12: HO.SuccOutInterEnbS1 | D12: eNB间S1切换出成功次数 | E12: 统计eNB间通过S1接口的切换出的完成阶段成功结束的次数。 单独统计QCI=1和2的次数。 | F12: 源eNB收到MME发送的“UE上下文释放命令”消息（UE CONTEXT RELEASE COMMAND）（3GPP TS 36.413），指示eNB间通过S1接口的切换出执行成功。 | G12: CC | H12: 整数 | I12: 次 | J12: EutranCellTdd EutranCellFdd | K12: 15分钟 | L12: 15分钟 | M12: 是
B13: CB | C13: HO.SuccOutInterEnbS1.eMTC | D13: eMTC终端eNB间S1切换出成功次数 | N13: CB条件：eMTC功能开启时，针对eMTC终端的统计
B14: A | C14: HO.SuccOutInterEnbS1.1 | D14: VoLTE用户eNB间S1切换出成功次数
B15: A | C15: HO.SuccOutInterEnbS1.2 | D15: QCI2承载eNB间S1切换出成功次数 | E15: 统计eNB间通过S1接口的切换出的完成阶段成功结束的次数。 | F15: 源eNB收到MME发送的“UE上下文释放命令”消息（UE CONTEXT RELEASE COMMAND）（3GPP TS 36.413），指示eNB间通过S1接口的切换出执行成功。 | G15: CC | H15: 整数 | I15: 次 | K15: 15分钟 | L15: 15分钟 | M15: 是
A16: ENBHD05 | B16: B | C16: HO.AvgTimeInterEnbS1 | D16: eNB间S1切换平均时长 | E16: 统计eNB间通过S1接口的切换的平均时长。 | F16: 取成功的eNB间S1切换的切换时长的平均值。切换时长等于源eNB向MME发送的“切换请求”消息（HANDOVER REQUIRED）（3GPP TS 36.413）与源eNB收到MME发送的“UE上下文释放命令”消息（UE CONTEXT RELEASE COMMAND）之间的时间间隔。 | G16: DER(n=1) | H16: 整数 | I16: ms | J16: EutranCellTdd EutranCellFdd | K16: 15分钟 | L16: 15分钟 | M16: 否 | N16: 无成功切换时此值报“-”（英文减号）
A17: ENBHD06 | B17: B | C17: HO.CancelOutInterEnbS1 | D17: eNB间S1切换出取消次数 | E17: 统计eNb间通过S1接口的切换，发出请求后又取消的次数。 单独统计QCI=1的次数。 | F17: 源eNB向MME发送“切换取消”（Handover Cancel）（3GPP TS 36.413)，指示切换取消。 | G17: CC | H17: 整数 | I17: 次 | J17: EutranCellTdd EutranCellFdd | K17: 15分钟 | L17: 15分钟 | M17: 是
B18: CB | C18: HO.CancelOutInterEnbS1.eMTC | D18: eMTC终端eNB间S1切换出取消次数 | N18: CB条件：eMTC功能开启时，针对eMTC终端的统计
B19: B | C19: HO.CancelOutInterEnbS1.1 | D19: VoLTE用户eNB间S1切换出取消次数 | E19: 统计eNb间通过S1接口的切换，发出请求后又取消的次数。 | F19: 源eNB向MME发送“切换取消”（Handover Cancel）（3GPP TS 36.413)，指示切换取消。 | G19: CC | H19: 整数 | I19: 次 | K19: 15分钟 | L19: 15分钟 | M19: 是
A20: ENBHD07 | B20: A | C20: HO.AttOutInterEnbX2 | D20: eNB间X2切换出请求次数 | E20: 统计eNB间通过X2接口的切换出请求次数。 单独统计QCI=1和2的次数。 | F20: 源eNB向目标eNB发送的“切换请求”消息（HANDOVER REQUEST）（3GPP TS 36.423），指示eNB间通过X2接口的切换出准备请求。向不同小区发送的同一切换准备请求，重复统计。 | G20: CC | H20: 整数 | I20: 次 | J20: EutranCellTdd EutranCellFdd | K20: 15分钟 | L20: 15分钟 | M20: 是
B21: CB | C21: HO.AttOutInterEnbX2.eMTC | D21: eMTC终端eNB间X2切换出请求次数 | N21: CB条件：eMTC功能开启时，针对eMTC终端的统计
B22: A | C22: HO.AttOutInterEnbX2.1 | D22: VoLTE用户eNB间X2切换出请求次数
A23: ENBHD07 | B23: A | C23: HO.AttOutInterEnbX2.2 | D23: QCI2承载eNB间X2切换出请求次数 | E23: 统计eNB间通过X2接口的切换出请求次数。 单独统计QCI=1的次数。 | F23: 源eNB向目标eNB发送的“切换请求”消息（HANDOVER REQUEST）（3GPP TS 36.423），指示eNB间通过X2接口的切换出准备请求。向不同小区发送的同一切换准备请求，重复统计。 | G23: CC | H23: 整数 | I23: 次 | K23: 15分钟 | L23: 15分钟 | M23: 是
A24: ENBHD08 | B24: B | C24: HO.SuccOutPrepInterEnbX2 | D24: eNB间X2切换出准备成功次数 | E24: 统计eNB间通过X2接口的切换出准备成功次数。 单独统计QCI=1的次数。 | F24: 源eNB收到目标eNB发送的“切换请求确认”消息（HANDOVER REQUEST ACKNOWLEDGE）（3GPP TS 36.423），指示eNB间X2切换出准备成功。 | G24: CC | H24: 整数 | I24: 次 | J24: EutranCellTdd EutranCellFdd | K24: 15分钟 | L24: 15分钟 | M24: 是
B25: CB | C25: HO.SuccOutPrepInterEnbX2.eMTC | D25: eMTC终端eNB间X2切换出准备成功次数 | N25: CB条件：eMTC功能开启时，针对eMTC终端的统计
A26: ENBHD08 | B26: B | C26: HO.SuccOutPrepInterEnbX2.1 | D26: VoLTE用户eNB间X2切换出准备成功次数 | E26: 统计eNB间通过X2接口的切换出准备成功次数。 单独统计QCI=1的次数。 | F26: 源eNB收到目标eNB发送的“切换请求确认”消息（HANDOVER REQUEST ACKNOWLEDGE）（3GPP TS 36.423），指示eNB间X2切换出准备成功。 | G26: CC | H26: 整数 | I26: 次 | K26: 15分钟 | L26: 15分钟 | M26: 是
A27: ENBHD09 | B27: B | C27: HO.AttOutExecInterEnbX2 | D27: eNB间X2切换出执行请求次数 | E27: 统计eNB间通过X2接口的切换出执行请求次数。 单独统计QCI=1的次数。 | F27: eNB向UE发送携带mobilityControlInfo 的“RRC连接重配置”消息（RRCConnectionReconfiguration），表示eNB间X2切换出执行请求。（3GPP TS 36.331） | G27: CC | H27: 整数 | I27: 次 | J27: EutranCellTdd EutranCellFdd | K27: 15分钟 | L27: 15分钟 | M27: 否
B28: CB | C28: HO.AttOutExecInterEnbX2.eMTC | D28: eMTC终端eNB间X2切换出执行请求次数 | N28: CB条件：eMTC功能开启时，针对eMTC终端的统计
A29: ENBHD09 | B29: B | C29: HO.AttOutExecInterEnbX2.1 | D29: VoLTE用户eNB间X2切换出执行请求次数 | F29: eNB向UE发送携带mobilityControlInfo 的“RRC连接重配置”消息（RRCConnectionReconfiguration），表示eNB间X2切换出执行请求。（3GPP TS 36.331） | G29: CC | H29: 整数 | I29: 次 | K29: 15分钟 | L29: 15分钟 | M29: 否
A30: ENBHD10 | B30: A | C30: HO.SuccOutInterEnbX2 | D30: eNB间X2切换出成功次数 | E30: 统计eNB间通过X2接口的切换出完成过程成功结束的次数。 单独统计QCI=1和2的次数。 | F30: 源eNB收到目标eNB发送的“UE上下文释放”消息（UE CONTEXT RELEASE）（3GPP TS 36.423），指示eNB间通过X2接口的切换出执行成功。 | G30: CC | H30: 整数 | I30: 次 | J30: EutranCellTdd EutranCellFdd | K30: 15分钟 | L30: 15分钟 | M30: 是
B31: CB | C31: HO.SuccOutInterEnbX2.eMTC | D31: eMTC终端eNB间X2切换出成功次数 | N31: CB条件：eMTC功能开启时，针对eMTC终端的统计
B32: A | C32: HO.SuccOutInterEnbX2.1 | D32: VoLTE用户eNB间X2切换出成功次数
A33: ENBHD10 | B33: A | C33: HO.SuccOutInterEnbX2.2 | D33: QCI2承载eNB间X2切换出成功次数 | E33: 统计eNB间通过X2接口的切换出完成过程成功结束的次数。 单独统计QCI=1的次数。 | F33: 源eNB收到目标eNB发送的“UE上下文释放”消息（UE CONTEXT RELEASE）（3GPP TS 36.423），指示eNB间通过X2接口的切换出执行成功。 | G33: CC | H33: 整数 | I33: 次 | K33: 15分钟 | L33: 15分钟 | M33: 是
A34: ENBHD11 | B34: B | C34: HO.AvgTimeInterEnbX2 | D34: eNB间X2切换平均时长 | E34: 统计eNB间通过X2接口的切换的平均时长。 | F34: 取成功的eNB间X2切换的切换时长的平均值。切换时长等于源eNB向目标eNB发送的“切换请求”消息（HANDOVER REQUEST）（3GPP TS 36.423）与源eNB收到目标eNB发送的“UE上下文释放”消息（UE CONTEXT RELEASE）（3GPP TS 36.423）之间的时间间隔。 | G34: DER(n=1) | H34: 整数 | I34: ms | J34: EutranCellTdd EutranCellFdd | K34: 15分钟 | L34: 15分钟 | M34: 否 | N34: 无成功切换时此值报“-”（英文减号）
A35: ENBHD12 | B35: B | C35: HO.CancelOutInterEnbX2 | D35: eNB间X2切换出取消次数 | E35: 统计eNb间通过X2接口的切换，发出请求后又取消的次数。 单独统计QCI=1的次数。 | F35: 源eNB向目标eNB发送“切换取消”（Handover Cancel）（3GPP TS 36.423)，指示切换取消。 | G35: CC | H35: 整数 | I35: 次 | J35: EutranCellTdd EutranCellFdd | K35: 15分钟 | L35: 15分钟 | M35: 是
B36: CB | C36: HO.CancelOutInterEnbX2.eMTC | D36: eMTC终端eNB间X2切换出取消次数 | N36: CB条件：eMTC功能开启时，针对eMTC终端的统计
A37: ENBHD12 | B37: B | C37: HO.CancelOutInterEnbX2.1 | D37: VoLTE用户eNB间X2切换出取消次数 | E37: 统计eNb间通过X2接口的切换，发出请求后又取消的次数。 单独统计QCI=1的次数。 | F37: 源eNB向目标eNB发送“切换取消”（Handover Cancel）（3GPP TS 36.423)，指示切换取消。 | G37: CC | H37: 整数 | I37: 次 | K37: 15分钟 | L37: 15分钟 | M37: 是
A38: ENBHD13 | B38: A | C38: HO.AttOutIntraEnb | D38: eNB内切换出请求次数 | E38: 统计eNB内小区间切换出请求次数。 单独统计QCI=1和2的次数。 | F38: eNB向UE发送携带mobilityControlInfo 的“RRC连接重配置”消息（RRCConnectionReconfiguration），指示eNB内小区间切换出请求。（3GPP TS 36.331） | G38: CC | H38: 整数 | I38: 次 | J38: EutranCellTdd EutranCellFdd | K38: 15分钟 | L38: 15分钟 | M38: 否
B39: CB | C39: HO.AttOutIntraEnb.eMTC | D39: eMTC终端eNB内切换出请求次数 | N39: CB条件：eMTC功能开启时，针对eMTC终端的统计
B40: A | C40: HO.AttOutIntraEnb.1 | D40: VoLTE用户eNB内切换出请求次数
...

Sheet HE
A1: 统计编码 | B1: 重要度 | C1: 英文名称 | D1: 中文名称 | E1: 定义 | F1: 触发点 | G1: 采集方式 | H1: 数据类型 | I1: 单位 | J1: 空间粒度 | K1: 时间粒度 | L1: 上报周期 | M1: 测试要求 | N1: 备注
A2: ENBHE01 | B2: C | C2: IRATHO.AttOutGeran | D2: 切换至2G请求次数 | E2: 统计系统间切换出请求次数（EPS->GERAN）。 | F2: 源eNB向MME发送的“切换请求”消息（HANDOVER REQUIRED），Handover Type IE（LTEtoGERAN）指示系统间（EUTRAN->GERAN）切换请求。（3GPP TS36.413） | G2: CC | H2: 整数 | I2: 次 | J2: EutranCellTdd EutranCellFdd | K2: 15分钟 | L2: 15分钟 | M2: 是 | N2: 在中国移动场景，也就是eSRVCC切换请求次数
A3: ENBHE02 | B3: C | C3: IRATHO.SuccPrepOutGeran | D3: 切换至2G准备成功次数 | E3: 统计系统间切换出准备成功次数（EPS-> GERAN）。 | F3: 源eNB收到MME发送的“切换命令”消息（HANDOVER COMMAND），指示系统间（EUTRAN-> GERAN）切换准备成功。（3GPP TS36.413） | G3: CC | H3: 整数 | I3: 次 | J3: EutranCellTdd EutranCellFdd | K3: 15分钟 | L3: 15分钟 | M3: 是 | N3: 在中国移动场景，也就是eSRVCC切换准备成功次数
A4: ENBHE03 | B4: C | C4: IRATHO.FailPrepOutGeran | D4: 切换至2G准备失败次数 | E4: 统计系统间切换出准备失败次数（EPS-> GERAN），按原因统计。 | F4: 源eNB收到MME发送的“切换准备失败”消息（HANDOVER PREPARATION FAILURE），或定时器超时，指示系统间（EUTRAN-> GERAN）切换准备失败，按原因统计。（3GPP TS36.413） | G4: CC | H4: 整数 | I4: 次 | J4: EutranCellTdd EutranCellFdd | K4: 15分钟 | L4: 15分钟 | M4: 是 | N4: 在中国移动场景，也就是eSRVCC切换准备失败次数
B5: C | C5: IRATHO.FailPrepOutGeran._Cause | D5: 分原因的切换至2G准备失败次数
A6: ENBHE04 | B6: C | C6: IRATHO.SuccOutGeran | D6: 切换至2G成功次数 | E6: 统计系统间切换出执行成功次数（EPS-> GERAN）。 | F6: 源eNB接收到MME发送的“UE上下文释放”消息（UE CONTEXT RELEASE COMMAND），且消息中携带原因值为Successful Handover，指示系统间（EUTRAN-> GERAN）切换执行成功。（3GPP TS36.413） | G6: CC | H6: 整数 | I6: 次 | J6: EutranCellTdd EutranCellFdd | K6: 15分钟 | L6: 15分钟 | M6: 是 | N6: 在中国移动场景，也就是eSRVCC切换成功次数
A7: ENBHE05 | B7: A | C7: IRATHO.AvgTimeOutGeran | D7: 切换至2G平均时长 | E7: 统计系统间切换出的平均时长（EPS-> GERAN）。 | F7: 各次成功的LTE至2G切换的切换时长的平均值。切换时长为源eNB向MME发送的HANDOVER REQUIRED(Handover Type IE指示为LTEtoGERAN）消息和源eNB接收到MME发送的UE CONTEXT RELEASE COMMAND消息之间的时长。 切换执行时长为源eNB接收到MME发送的HANDOVER COMMAND消息到源eNB接收到MME发送的UE CONTEXT RELEASE COMMAND消息（原因值为Successful Handvoer）之间的时长。 | G7: DER(n=1) | H7: 整数 | I7: ms | J7: EutranCellTdd EutranCellFdd | K7: 15分钟 | L7: 15分钟 | M7: 否 | N7: 无成功切换时此值报“-”（英文减号）
B8: A | C8: IRATHO.AvgTimeOutGeran.Exec | D8: 至2G切换执行平均时长 | G8: DER(n=1) | H8: 整数 | I8: ms | K8: 15分钟 | L8: 15分钟 | M8: 否 | N8: 无成功切换时此值报0
A9: ENBHE06 | B9: CC | C9: IRATHO.AttOutUtran | D9: 切换至3G请求次数 | E9: 统计系统间分组域切换出准备请求次数（EPS-> UTRAN）。 | F9: 源eNB向MME发送的“切换请求”消息（HANDOVER REQUIRED），指示系统间（EUTRAN-> UTRAN）分组域切换准备请求。（3GPP TS36.413） | G9: CC | H9: 整数 | I9: 次 | J9: EutranCellTdd EutranCellFdd | K9: 15分钟 | L9: 15分钟 | M9: 否 | N9: CC条件：存在3G场景时
A10: ENBHE07 | B10: CC | C10: IRATHO.SuccPrepOutUtran | D10: 切换至3G准备成功次数 | E10: 统计系统间分组域切换出准备成功次数（EPS-> UTRAN）。 | F10: 源eNB收到MME发送的“切换命令”消息（HANDOVER COMMAND），指示系统间（EUTRAN-> UTRAN）分组域切换准备成功。（3GPP TS36.413） | G10: CC | H10: 整数 | I10: 次 | J10: EutranCellTdd EutranCellFdd | K10: 15分钟 | L10: 15分钟 | M10: 否
A11: ENBHE08 | B11: CC | C11: IRATHO.FailPrepOutUtran | D11: 切换至3G准备失败次数 | E11: 统计系统间分组域切换出准备失败次数（EPS-> UTRAN），按原因统计。 | F11: 源eNB收到MME发送的“切换准备失败”消息（HANDOVER PREPARATION FAILURE），或定时器超时，指示系统间（EUTRAN-> UTRAN）分组域切换准备失败，按原因统计。（3GPP TS36.413） | G11: CC | H11: 整数 | I11: 次 | J11: EutranCellTdd EutranCellFdd | K11: 15分钟 | L11: 15分钟 | M11: 否
B12: CC | C12: IRATHO.FailPrepOutUtran._Cause | D12: 分原因的切换至3G准备失败次数
A13: ENBHE09 | B13: CC | C13: IRATHO.SuccOutUtran | D13: 切换至3G成功次数 | E13: 统计系统间分组域切换出执行成功次数（EPS-> UTRAN）。 | F13: 源eNB接收到MME发送的“UE上下文释放”消息（UE CONTEXT RELEASE COMMAND），且消息中携带原因值为Successful Handover，指示系统间（EUTRAN-> UTRAN）分组域切换执行成功。（3GPP TS36.413） | G13: CC | H13: 整数 | I13: 次 | J13: EutranCellTdd EutranCellFdd | K13: 15分钟 | L13: 15分钟 | M13: 否
A14: ENBHE10 | B14: CC | C14: IRATHO.AvgTimeOutUtran | D14: 切换至3G平均时长 | E14: 统计系统间分组域切换出的平均时长（EPS-> UTRAN）。 | F14: 各次成功的LTE至3G切换的切换时长的平均值。切换时长为源eNB向MME发送的HANDOVER REQUIRED(Handover Type IE指示为LTEtoUTRAN）消息和源eNB接收到MME发送的UE CONTEXT RELEASE COMMAND消息之间的时长。 | G14: DER(n=1) | H14: 整数 | I14: ms | J14: EutranCellTdd EutranCellFdd | K14: 15分钟 | L14: 15分钟 | M14: 否 | N14: 无成功切换时此值报“-”（英文减号） CC条件：存在3G场景时
A15: ENBHE11 | B15: C | C15: IRATHO.AttIncGeran | D15: 2G切入请求次数 | E15: 统计系统间分组域切换入准备请求次数（GERAN->EPS）。 | F15: 目标eNB收到MME发送的“切换请求”消息（HANDOVER REQUEST），Handover Type IE（GERANtoLTE）指示系统间分组域切换入准备请求。（3GPP TS 36.413）。 | G15: CC | H15: 整数 | I15: 次 | J15: EutranCellTdd EutranCellFdd | K15: 15分钟 | L15: 15分钟 | M15: 是
A16: ENBHE12 | B16: C | C16: IRATHO.SuccPrepIncGeran | D16: 2G切入准备成功次数 | E16: 统计系统间分组域切换入准备成功次数（GERAN->EPS）。 | F16: 目标eNB向MME发送“切换请求确认”消息（HANDOVER REQUEST ACKNOWLEDGE），指示系统间（GERAN->EUTRAN）分组域切换入准备成功。（3GPP TS 36.413）。 | G16: CC | H16: 整数 | I16: 次 | J16: EutranCellTdd EutranCellFdd | K16: 15分钟 | L16: 15分钟 | M16: 是
A17: ENBHE13 | B17: C | C17: IRATHO.FailPrepIncGeran | D17: 2G切入准备失败次数 | E17: 统计系统间分组域切换入准备失败次数（GERAN->EPS），按原因统计。 | F17: 目标eNB向MME发送“切换失败”消息（HANDOVER FAILURE），或定时器超时，指示系统间（GERAN->EUTRAN）分组域切换入准备失败，按原因统计。（3GPP TS 36.413）。 | G17: CC | H17: 整数 | I17: 次 | J17: EutranCellTdd EutranCellFdd | K17: 15分钟 | L17: 15分钟 | M17: 是
B18: C | C18: IRATHO.FailPrepIncGeran._Cause | D18: 分原因的2G切入准备失败次数
A19: ENBHE14 | B19: C | C19: IRATHO.SuccIncGeran | D19: 2G切入成功次数 | E19: 统计系统间分组域切换入成功次数（GERAN->EPS）。 | F19: 目标eNB向MME发送“切换通知”消息(Handover Notify),指示由2G切入LTE成功。(3GPP TS 36.413) | G19: CC | H19: 整数 | I19: 次 | J19: EutranCellTdd EutranCellFdd | K19: 15分钟 | L19: 15分钟 | M19: 是
A20: ENBHE15 | B20: CC | C20: IRATHO.AttIncUtran | D20: 3G切入请求次数 | E20: 统计系统间分组域切换入准备请求次数（UTRAN->EPS）。 | F20: 目标eNB收到MME发送的“切换请求”消息（HANDOVER REQUEST），Handover Type IE（UTRANtoLTE）指示系统间（UTRAN->EUTRAN）分组域切换入准备请求。（3GPP TS 36.413）。 | G20: CC | H20: 整数 | I20: 次 | J20: EutranCellTdd EutranCellFdd | K20: 15分钟 | L20: 15分钟 | M20: 否 | N20: CC条件：存在3G场景时
A21: ENBHE16 | B21: CC | C21: IRATHO.SuccPrepIncUtran | D21: 3G切入准备成功次数 | E21: 统计系统间分组域切换入准备成功次数（UTRAN->EPS）。 | F21: 目标eNB向MME发送“切换请求确认”消息（HANDOVER REQUEST ACKNOWLEDGE），指示系统间（UTRAN->EUTRAN）分组域切换入准备成功。（3GPP TS 36.413）。 | G21: CC | H21: 整数 | I21: 次 | J21: EutranCellTdd EutranCellFdd | K21: 15分钟 | L21: 15分钟 | M21: 否
A22: ENBHE17 | B22: CC | C22: IRATHO.FailPrepIncUtran | D22: 3G切入准备失败次数 | E22: 统计系统间分组域切换入准备失败次数（UTRAN->EPS），按原因统计。 | F22: 目标eNB向MME发送“切换失败”消息（HANDOVER FAILURE），或定时器超时，指示系统间（UTRAN->EUTRAN）分组域切换入准备失败，按原因统计。（3GPP TS 36.413）。 | G22: CC | H22: 整数 | I22: 次 | J22: EutranCellTdd EutranCellFdd | K22: 15分钟 | L22: 15分钟 | M22: 否
B23: CC | C23: IRATHO.FailPrepIncUtran._Cause | D23: 分原因的3G切入准备失败次数
A24: ENBHE18 | B24: CC | C24: IRATHO.SuccIncUtran | D24: 3G切入成功次数 | E24: 统计系统间分组域切换入成功次数（UTRAN->EPS）。 | F24: 目标eNB向MME发送“切换通知”消息(Handover Notify),指示由3G切入LTE成功。(3GPP TS 36.413) | G24: CC | H24: 整数 | I24: 次 | J24: EutranCellTdd EutranCellFdd | K24: 15分钟 | L24: 15分钟 | M24: 否
A25: ENBHE19 | B25: C | C25: IRATHO.AttOut5GS | D25: 切换至5G请求次数 | E25: 统计系统间切换出请求次数（EPS->5GS）。 | F25: 源eNB向MME发送的“切换请求”消息（HANDOVER REQUIRED），Handover Type IE（EPSto5GS）指示系统间（EPS->5GS）切换请求。（3GPP TS36.413） | G25: CC | H25: 整数 | I25: 次 | J25: EutranCellTdd EutranCellFdd | K25: 15分钟 | L25: 15分钟 | M25: 是
A26: ENBHE20 | B26: C | C26: IRATHO.SuccPrepOut5G | D26: 切换至5G准备成功次数 | E26: 统计系统间切换出准备成功次数（EPS->5GS）。 | F26: 源eNB收到MME发送的“切换命令”消息（HANDOVER COMMAND），指示系统间（EPS->5GS）切换准备成功。（3GPP TS36.413） | G26: CC | H26: 整数 | I26: 次 | J26: EutranCellTdd EutranCellFdd | K26: 15分钟 | L26: 15分钟 | M26: 是
A27: ENBHE21 | B27: C | C27: IRATHO.FailPrepOut5G | D27: 切换至5G准备失败次数 | E27: 统计系统间切换出准备失败次数（EPS->5GS），按原因统计。 | F27: 源eNB收到MME发送的“切换准备失败”消息（HANDOVER PREPARATION FAILURE），或定时器超时，指示系统间（EPS->5GS）切换准备失败，按原因统计。（3GPP TS36.413） | G27: CC | H27: 整数 | I27: 次 | J27: EutranCellTdd EutranCellFdd | K27: 15分钟 | L27: 15分钟 | M27: 是
B28: C | C28: IRATHO.FailPrepOut5G._Cause | D28: 分原因的切换至5G准备失败次数
A29: ENBHE22 | B29: C | C29: IRATHO.SuccOut5G | D29: 切换至5G成功次数 | E29: 统计系统间切换出执行成功次数（EPS->5GS）。 | F29: 源eNB接收到MME发送的“UE上下文释放”消息（UE CONTEXT RELEASE COMMAND），且消息中携带原因值为Successful Handover，指示系统间（EPS->5GS）切换执行成功。（3GPP TS36.413） | G29: CC | H29: 整数 | I29: 次 | J29: EutranCellTdd EutranCellFdd | K29: 15分钟 | L29: 15分钟 | M29: 是
A30: ENBHE23 | B30: A | C30: IRATHO.AvgTimeOut5G | D30: 切换至5G平均时长 | E30: 统计系统间切换出的平均时长（EPS->5GS）。 | F30: 各次成功的LTE至5G切换的切换时长的平均值。切换时长为源eNB向MME发送的HANDOVER REQUIRED(Handover Type IE指示为EPSto5GS）消息和源eNB接收到MME发送的UE CONTEXT RELEASE COMMAND消息之间的时长。 切换执行时长为源eNB接收到MME发送的HANDOVER COMMAND消息到源eNB接收到MME发送的UE CONTEXT RELEASE COMMAND消息（原因值为Successful Handvoer）之间的时长。 | G30: DER(n=1) | H30: 整数 | I30: ms | J30: EutranCellTdd EutranCellFdd | K30: 15分钟 | L30: 15分钟 | M30: 否 | N30: 无成功切换时此值报“-”（英文减号）
B31: A | C31: IRATHO.AvgTimeOut5G.Exec | D31: 至5G切换执行平均时长
A32: ENBHE24 | B32: C | C32: IRATHO.AttInc5G | D32: 5G切入请求次数 | E32: 统计系统间切换入准备请求次数（5GS->EPS）。 | F32: 目标eNB收到MME发送的“切换请求”消息（HANDOVER REQUEST），Handover Type IE（5GStoEPS）指示系统间切换入准备请求。（3GPP TS 36.413）。 | G32: CC | H32: 整数 | I32: 次 | J32: EutranCellTdd EutranCellFdd | K32: 15分钟 | L32: 15分钟 | M32: 是
A33: ENBHE25 | B33: C | C33: IRATHO.SuccPrepInc5G | D33: 5G切入准备成功次数 | E33: 统计系统间切换入准备成功次数（5GS->EPS）。 | F33: 目标eNB向MME发送“切换请求确认”消息（HANDOVER REQUEST ACKNOWLEDGE），指示系统间（5GS->EPS）切换入准备成功。（3GPP TS 36.413）。 | G33: CC | H33: 整数 | I33: 次 | J33: EutranCellTdd EutranCellFdd | K33: 15分钟 | L33: 15分钟 | M33: 是
A34: ENBHE26 | B34: C | C34: IRATHO.FailPrepInc5G | D34: 5G切入准备失败次数 | E34: 统计系统间切换入准备失败次数（5GS->EPS），按原因统计。 | F34: 目标eNB向MME发送“切换失败”消息（HANDOVER FAILURE），或定时器超时，指示系统间（5GS->EPS）切换入准备失败，按原因统计。（3GPP TS 36.413）。 | G34: CC | H34: 整数 | I34: 次 | J34: EutranCellTdd EutranCellFdd | K34: 15分钟 | L34: 15分钟 | M34: 是
B35: C | C35: IRATHO.FailPrepInc5G._Cause | D35: 分原因的5G切入准备失败次数
A36: ENBHE27 | B36: C | C36: IRATHO.SuccInc5G | D36: 5G切入成功次数 | E36: 统计系统间切换入成功次数（5GS->EPS）。 | F36: 目标eNB向MME发送“切换通知”消息(Handover Notify),指示由5G切入LTE成功。(3GPP TS 36.413) | G36: CC | H36: 整数 | I36: 次 | J36: EutranCellTdd EutranCellFdd | K36: 15分钟 | L36: 15分钟 | M36: 是

Sheet HF
A1: 统计编码 | B1: 重要度 | C1: 英文名称 | D1: 中文名称 | E1: 定义 | F1: 触发点 | G1: 采集方式 | H1: 数据类型 | I1: 单位 | J1: 空间粒度 | K1: 时间粒度 | L1: 上报周期 | M1: 测试要求 | N1: 备注
A2: ENBHF01 | B2: B | C2: HO.AttOutPerRelation | D2: 系统内每相邻关系切换出请求次数 | E2: 统计系统内小区间切换出请求次数，并按切换原因分类统计。单独统计QCI=1的系统内每相邻关系切换出请求次数。 注：本测量不包括eNB内切换。 | F2: 源eNB向MME发送的“切换请求”(HANDOVER REQUIRED)(3GPP TS36.413)消息；或者源eNB向目标eNB发送的“切换请求”(HANDOVER REQUEST)（TS36.423）消息。 | G2: CC | H2: 整数 | I2: 次 | J2: EutranRelation | K2: 15分钟 | L2: 15分钟 | M2: 否
B3: C | C3: HO.AttOutPerRelation._Cause | D3: 分原因的系统内每相邻关系切换出请求次数
B4: B | C4: HO.AttOutPerRelation.1 | D4: QCI=1系统内每相邻关系切换出请求次数
A5: ENBHF02 | B5: B | C5: HO.SuccOutPrepPerRelation | D5: 系统内每相邻关系切换出准备成功次数 | E5: 统计系统内小区间切换出准备成功次数。 单独统计QCI=1的系统内每相邻关系切换出准备成功次数。 注：本测量不包括eNB内切换。 | F5: 源eNB收到MME发送的“切换命令”(HANDOVER COMMAND)(3GPP TS36.413)消息；或者源eNB收到目标eNB发送的“切换请求确认”(HANDOVER REQUEST ACKNOWLEDGE)（TS36.423）消息。 | G5: CC | H5: 整数 | I5: 次 | J5: EutranRelation | K5: 15分钟 | L5: 15分钟 | M5: 否
B6: B | C6: HO.SuccOutPrepPerRelation.1 | D6: QCI=1系统内每相邻关系切换出准备成功次数 | F6: 源eNB收到MME发送的“切换命令”(HANDOVER COMMAND)(3GPP TS36.413)消息；或者源eNB收到目标eNB发送的“切换请求确认”(HANDOVER REQUEST ACKNOWLEDGE)（TS36.423）消息。 | G6: CC | H6: 整数 | I6: 次 | K6: 15分钟 | L6: 15分钟 | M6: 否
A7: ENBHF03 | B7: B | C7: HO.AttOutExecPerRelation | D7: 系统内每相邻关系切换出执行请求次数 | E7: 统计系统内小区间切换出执行请求次数。单独统计QCI=1的系统内每相邻关系切换出执行请求次数。 注，本测量包括eNB内的切换。 | F7: 源eNB向UE发送包含“mobilityControlInformation”的“RRC连接重配”消息（RRCConnectionReconfiguration），指示系统内小区间切换出请求。（3GPP TS36.331） | G7: CC | H7: 整数 | I7: 次 | J7: EutranRelation | K7: 15分钟 | L7: 15分钟 | M7: 否
B8: B | C8: HO.AttOutExecPerRelation.1 | D8: QCI=1系统内每相邻关系切换出执行请求次数 | F8: 源eNB向UE发送包含“mobilityControlInformation”的“RRC连接重配”消息（RRCConnectionReconfiguration），指示系统内小区间切换出请求。（3GPP TS36.331） | G8: CC | H8: 整数 | I8: 次 | K8: 15分钟 | L8: 15分钟 | M8: 否
A9: ENBHF04 | B9: B | C9: HO.SuccOutPerRelation | D9: 系统内每相邻关系切换出成功次数 | E9: 统计系统内小区间切换成功次数。单独统计QCI=1系统内每相邻关系切换出成功次数。 | F9: 对于X2接口切换:源eNB收到目标eNB发送的“UE上下文释放”（UE CONTEXT RELEASE）（TS36.423)消息； 对于S1接口切换：源eNB收到MME发送的“UE上下文释放命令”（UE CONTEXT RELEASE COMMAND）(3GPP TS36.413)消息； 对于eNB内的切换：eNB收到UE发送的RRCConnectionReconfigurationComplete消息。 | G9: CC | H9: 整数 | I9: 次 | J9: EutranRelation | K9: 15分钟 | L9: 15分钟 | M9: 否
B10: B | C10: HO.SuccOutPerRelation.1 | D10: QCI=1系统内每相邻关系切换出成功次数 | F10: 对于X2接口切换:源eNB收到目标eNB发送的“UE上下文释放”（UE CONTEXT RELEASE）（TS36.423)消息； 对于S1接口切换：源eNB收到MME发送的“UE上下文释放命令”（UE CONTEXT RELEASE COMMAND）(3GPP TS36.413)消息； 对于eNB内的切换：eNB收到UE发送的RRCConnectionReconfigurationComplete消息。 | G10: CC | H10: 整数 | I10: 次 | K10: 15分钟 | L10: 15分钟 | M10: 否
A11: ENBHF05 | B11: C | C11: HO.OutFailTooEarly | D11: 过早切换出失败次数 | E11: 统计移动鲁棒性优化(MRO)相关的切换出失败次数 | F11: 通过检测eNB切换失败事件（3GPP TS 36.300），统计由于过早切换引起的切换出失败次数。 | G11: CC | H11: 整数 | I11: 次 | J11: EutranRelation | K11: 15分钟 | L11: 15分钟 | M11: 否
A12: ENBHF06 | B12: C | C12: HO.OutFailTooLate | D12: 过晚切换出失败次数 | E12: 统计移动鲁棒性优化(MRO)相关的切换出失败次数 | F12: 通过检测eNB切换失败事件（3GPP TS 36.300），统计由于过晚切换引起的切换出失败次数。 | G12: CC | H12: 整数 | I12: 次 | J12: EutranRelation | K12: 15分钟 | L12: 15分钟 | M12: 否
A13: ENBHF07 | B13: C | C13: HO.OutFailToWrongCell | D13: 到错误小区的切换出失败次数 | E13: 统计移动鲁棒性优化(MRO)相关的切换出失败次数 | F13: 通过检测eNB切换失败事件（3GPP TS 36.300），统计由于切换到错误小区引起的切换出失败次数。 | G13: CC | H13: 整数 | I13: 次 | J13: EutranRelation | K13: 15分钟 | L13: 15分钟 | M13: 否
A14: ENBHF08 | B14: B | C14: HO.OutPrepFail.CauseTCellNoResponse | D14: 系统内每相邻关系目标小区无响应原因导致的切换出准备失败次数 | E14: 统计由于定时器超时导致的切换出准备失败 | F14: S1切换时源eNB给MME发送HANDOVER REQUIRED消息后，定时器TS1RELOCprep超时，指示切换出准备失败（参见3GPP TS 36.413）；或X2切换时源eNB给目标eNB发送HANDOVER REQUEST消息后，定时器TRELOCprep超时，指示切换出准备失败（参见3GPP TS 36.423）。 | G14: CC | H14: 整数 | I14: 次 | J14: EutranRelation | K14: 15分钟 | L14: 15分钟 | M14: 是
A15: ENBHF09 | B15: B | C15: HO.OutPrepFail.CauseHOPrepFailureMsg | D15: 系统内每相邻关系目标小区回复切换准备失败消息导致切换出准备失败次数 | E15: 统计由于目标小区回复切换准备失败消息导致的切换出准备失败 | F15: S1切换时源eNB收到MME发送的“切换准备失败”消息（HANDOVER PREPARATION FAILURE）（3GPP TS 36.413），或X2切换时源eNB收到目标eNB发送的“切换准备失败”（HANDOVER PREPARATION FAILURE）消息。 | G15: CC | H15: 整数 | I15: 次 | J15: EutranRelation | K15: 15分钟 | L15: 15分钟 | M15: 是
A16: ENBHF10 | B16: B | C16: HO.PingPong | D16: 乒乓切换次数 | E16: 统计基于两两邻区关系的乒乓切换次数。 | F16: 根据用户的历史信息进行判断，如果用户从源小区切换到目标邻区，乒乓切换定时器超时前又成功切换回源小区，则统计值加1。 | G16: CC | H16: 整数 | I16: 次 | J16: EutranRelation | K16: 15分钟 | L16: 15分钟 | M16: 否

Sheet HG
A1: 统计编码 | B1: 重要度 | C1: 英文名称 | D1: 中文名称 | E1: 定义 | F1: 触发点 | G1: 采集方式 | H1: 数据类型 | I1: 单位 | J1: 空间粒度 | K1: 时间粒度 | L1: 上报周期 | M1: 测试要求 | N1: 备注
A2: ENBHG01 | B2: A | C2: PAG.PagReceived | D2: 寻呼记录接收个数 | E2: 统计E-UTRAN从MME收到的的寻呼个数。 | F2: eNB从MME成功收到的“寻呼”消息(PAGING),且TAI List含有本小区的TA（3GPP TS 36.413）。 | G2: CC | H2: 整数 | I2: 个 | J2: EutranCellTdd EutranCellFdd | K2: 15分钟 | L2: 15分钟 | M2: 否
A3: ENBHG02 | B3: CA | C3: PAG.PagDiscarded | D3: 寻呼记录丢弃个数 | E3: 统计eNB丢弃的寻呼个数。 | F3: 对本小区的寻呼记录，由于各种原因（例如拥塞等）直接丢弃的寻呼记录总数 | G3: CC | H3: 整数 | I3: 个 | J3: EutranCellTdd EutranCellFdd | K3: 15分钟 | L3: 15分钟 | M3: 否 | N3: CA条件：网络拥塞或故障时

Sheet HH
A1: 统计编码 | B1: 重要度 | C1: 英文名称 | D1: 中文名称 | E1: 定义 | F1: 触发点 | G1: 采集方式 | H1: 数据类型 | I1: 单位 | J1: 空间粒度 | K1: 时间粒度 | L1: 上报周期 | M1: 测试要求 | N1: 备注
A2: ENBHH01 | B2: A | C2: PDCP.UpOctUl | D2: 小区用户面上行字节数 | E2: 在测量周期内，累加小区用户面通过空口成功接收的PDCP SDU字节数，即小区用户面PDCP层从下层接收到的PDCP SDU字节数，并应该按照承载的QCI类型分类统计。 单独统计上行CA激活用户的小区用户面上行字节数。 | F2: 无 | G2: CC | H2: 实数 | I2: KByte | J2: EutranCellTdd EutranCellFdd | K2: 15分钟 | L2: 15分钟 | M2: 否 | N2: 1KByte=1000Byte
B3: CB | C3: PDCP.UpOctUl.eMTC | D3: eMTC终端小区用户面上行字节数 | N3: 注1：1KByte=1000Byte 注2：CB条件：eMTC功能开启时，针对eMTC终端的统计
B4: B | C4: PDCP.UpOctUl._Qci | D4: 分QCI的小区用户面上行字节数
B5: CA | C5: PDCP.UpOctUl.CA | D5: 上行CA激活用户的小区用户面上行字节数 | N5: CA条件：开启载波聚合功能时，进行相关统计
A6: ENBHH02 | B6: A | C6: PDCP.UpOctDl | D6: 小区用户面下行字节数 | E6: 在测量周期内，累加小区用户面通过空口成功发送的PDCP SDU字节数，即小区用户面PDCP层向下层发送的SDU字节数，并按照承载的QCI类型分类统计。成功发送定义为收到UE对PDCP SDU的最后一个分片的ACK确认，具体为UM模式下为MAC层ACK;AM模式下为RLC层ACK。字节数的统计在PDCP层，统计压缩之后的字节数。 单独统计下行CA激活用户的小区用户面下行字节数。 注1：该测量不包括切换过程中，通过X2或S1接口转发到其它eNB的PDCP SDU字节数。 注2：该测量不考虑低层是否重传或传送失败。 | F6: 无 | G6: CC | H6: 实数 | I6: KByte | J6: EutranCellTdd EutranCellFdd | K6: 15分钟 | L6: 15分钟 | M6: 否 | N6: 1KByte=1000Byte
B7: CB | C7: PDCP.UpOctDl.eMTC | D7: eMTC终端小区用户面下行字节数 | N7: 注1：1KByte=1000Byte 注2：CB条件：eMTC功能开启时，针对eMTC终端的统计
B8: B | C8: PDCP.UpOctDl._Qci | D8: 分QCI的小区用户面下行字节数 | N8: 1KByte=1000Byte 支持扩展QCI
B9: CA | C9: PDCP.UpOctDl.CA | D9: 下行CA激活用户的小区用户面下行字节数 | N9: 注1：1KByte=1000Byte 注2：CA条件：开启载波聚合功能时，进行相关统计
